Workbook
Name 会社名: [1]顧客リスト!$C$2:$N$2

Sheet 見積・請求書→

Sheet トヨタ紡織→
A1: 2024年 | C1: エンジニアリングサービス部 見積書・請求書発行管理台帳 | H1: 見積書(税抜金額) | M1: 請求書(税抜金額) | R1: 出張費請求書(税抜金額) | V1: 業務委託契約書
A2: 企業名： | C2: トヨタ紡織(株)
A3: タスク | B3: No | C3: 部署名 | D3: 見積/請求番号 | E3: 発注番号 | F3: 業務計画書No | G3: 案件名 | H3: 見積金額 | I3: 見積月 | J3: 発行日 | K3: 発行者 | L3: 枝番 | M3: 請求金額 | N3: 請求月 | O3: 発行日 | P3: 発行者 | Q3: 番号 | R3: 金額 | S3: 請求月 | T3: 発行日 | U3: 発行者 | V3: 収入印紙 | W3: 返送日 | X3: 送付先 | Y3: 発行者 | Z3: 備考

Sheet A1
A1: 2025年 | C1: エンジニアリングサービス部 見積書・請求書発行管理台帳 | H1: 見積書(税抜金額)
A2: 企業名： | C2: トヨタ紡織(株)
A3: タスク | B3: No | C3: 部署名 | D3: 見積/請求番号 | E3: 発注番号 | F3: 業務計画書No | G3: 案件名 | H3: 見積金額 | I3: 見積月 | J3: 発行日 | K3: 発行者 | L3: 備考
A4: 完了 | B4: 1 | C4: 第1シート設計部 | D4: 16100016 | E4: A13-R22-010 | F4: - | G4: DASデータまとめ | I4: 1月 | J4: 44903 | K4: 鈴木
A5: 完了 | B5: 2 | C5: 第1シート設計部 | D5: 16100017 | E5: A13-R22-011 | F5: - | G5: DASデータまとめ | I5: 2月 | J5: 44937 | K5: 鈴木
A6: 完了 | B6: 3 | C6: 第1シート設計部 | D6: 16100018 | E6: A13-R22-014 | F6: - | G6: DASデータまとめ | I6: 3月 | J6: 44966 | K6: 鈴木
A7: 完了 | B7: 4 | C7: 第1シート設計部 | D7: 16100019 | E7: A13-R22-016 | F7: - | G7: DASデータまとめ | I7: 4月 | J7: 44999 | K7: 鈴木
A8: 完了 | B8: 5 | C8: 第1シート設計部 | D8: 16100020 | F8: - | G8: DASデータまとめ | I8: 5月 | J8: 45023 | K8: 鈴木
A9: 完了 | B9: 6 | C9: 第1シート設計部 | D9: 16100021 | F9: - | G9: DASデータまとめ | I9: 6月 | J9: 45063 | K9: 鈴木
A10: 完了 | B10: 7 | C10: 第1シート設計部 | D10: 16100022 | F10: - | G10: DASデータまとめ | I10: 7月 | J10: 45085 | K10: 鈴木
A11: 完了 | B11: 8 | C11: 第1シート設計部 | D11: 16100023 | F11: - | G11: DASデータまとめ | I11: 8月 | J11: 45112 | K11: 鈴木
A12: 完了 | B12: 9 | C12: 第1シート設計部 | D12: 16100024 | F12: - | G12: DASデータまとめ | I12: 9月 | J12: 45148 | K12: 鈴木
A13: 完了 | B13: 10 | C13: 第1シート設計部 | D13: 16100025 | F13: - | G13: DASデータまとめ | I13: 10月 | J13: 45183 | K13: 齊藤
A14: 完了 | B14: 11 | C14: 第1シート設計部 | D14: 16100026 | F14: - | G14: DASデータまとめ | I14: 11月 | J14: 45210 | K14: 齊藤
A15: 完了 | B15: 12 | C15: 第1シート設計部 | D15: 16100027 | F15: - | G15: DASデータまとめ | I15: 12月 | J15: 45243 | K15: 齊藤
A16: 進行中 | B16: 13 | C16: 第1シート設計部 | D16: 16100028 | F16: - | G16: DASデータまとめ | I16: 1月 | J16: 45266 | K16: 齊藤
B17: 14 | C17: 第1シート設計部 | D17: 16100029 | F17: - | G17: DASデータまとめ | I17: 2月 | J17: 45309 | K17: 齊藤
B18: 15 | C18: 第1シート設計部 | D18: 16100030 | F18: - | G18: DASデータまとめ | I18: 3月 | J18: 45328 | K18: 齊藤
B19: 16 | C19: 第1シート設計部 | D19: 16100031 | F19: - | G19: DASデータまとめ | I19: 4月 | J19: 45364 | K19: 齊藤
B20: 17 | C20: 第1シート設計部 | D20: 16100032 | F20: - | G20: DASデータまとめ | I20: 5月 | J20: 45390 | K20: 齊藤
B21: 18 | C21: 第1シート設計部 | D21: 16100033 | F21: - | G21: DASデータまとめ | I21: 6月 | J21: 45422 | K21: 齊藤
B22: 19 | C22: 第1シート設計部 | D22: 16100034 | F22: - | G22: DASデータまとめ | I22: 7月 | J22: 45453 | K22: 齊藤
B23: 20 | C23: 第1シート設計部 | D23: 16100035 | F23: - | G23: DASデータまとめ | I23: 8月 | J23: 45481 | K23: 齊藤
B24: 21 | C24: 第1シート設計部 | D24: 16100036 | F24: - | G24: DASデータまとめ | I24: 9月 | J24: 45510 | K24: 齊藤
B25: 22 | C25: 第1シート設計部 | D25: 16100037 | F25: - | G25: DASデータまとめ | I25: 10月 | J25: 45544 | K25: 久目形
B26: 23 | C26: 第1シート設計部 | D26: 16100038 | F26: - | G26: DASデータまとめ | I26: 11月 | J26: 45583 | K26: 久目形
B27: 24 | C27: 第1シート設計部 | D27: 16100039 | F27: - | G27: DASデータまとめ | I27: 12月 | J27: 45604 | K27: 久目形
B28: 25 | C28: 第1シート設計部 | D28: 16100040 | F28: - | G28: DASデータまとめ | I28: 1月 | J28: 45997 | K28: 久目形
B29: 26 | C29: 第1シート設計部 | D29: 16100041 | F29: - | G29: DASデータまとめ | I29: 2月 | J29: 45672 | K29: 久目形
B30: 27 | D30: 16100042
B31: 28 | C31: 第1シート設計部 | D31: 16100043 | F31: - | G31: DASデータまとめ | I31: 3月 | J31: 45699 | K31: 久目形
B32: 29 | C32: 第1シート設計部 | D32: 16100044 | F32: - | G32: DASデータまとめ | I32: 4月 | J32: 45735 | K32: 久目形
B33: 30 | C33: 第1シート設計部 | D33: 16100045 | F33: - | G33: DASデータまとめ | I33: ５月 | J33: 45761 | K33: 丸山
B34: 31 | C34: 第1シート設計部 | D34: 16100046 | F34: - | G34: DASデータまとめ | I34: 6月 | J34: ’25/5/13 | K34: 丸山
B35: 32 | C35: 第1シート設計部 | D35: 16100047 | F35: - | G35: DASデータまとめ | I35: 7月 | J35: ’25/6/9 | K35: 久目形
B36: 33 | C36: 第1シート設計部 | D36: 16100048 | F36: - | G36: DASデータまとめ | I36: 8月 | J36: ’25/7/4 | K36: 久目形
B37: 34 | C37: 第1シート設計部 | D37: 16100049 | F37: - | G37: DASデータまとめ | I37: 9月 | J37: ’25/8/6 | K37: 久目形
B38: 35 | C38: 第1シート設計部 | D38: 16100050 | F38: - | G38: DASデータまとめ | I38: 10月 | J38: ’25/9/8 | K38: 久目形
B39: 36 | C39: 第1シート設計部 | D39: 16100051 | F39: - | G39: DASデータまとめ | I39: 11月 | J39: ’25/10/6 | K39: 久目形
B40: 37 | C40: 第1シート設計部 | D40: 16100052 | F40: - | G40: DASデータまとめ | I40: 12月 | J40: ’25/11/10 | K40: 久目形
...

Sheet A11
A1: 2024年 | C1: エンジニアリングサービス部 見積書・請求書発行管理台帳 | H1: 見積書(税抜金額)
A2: 企業名： | C2: トヨタ紡織(株)
A3: タスク | B3: No | C3: 部署名 | D3: 見積/請求番号 | E3: 発注番号 | F3: 業務計画書No | G3: 案件名 | H3: 見積金額 | I3: 見積月 | J3: 発行日 | K3: 発行者 | L3: 備考
A4: 完了 | B4: 1 | C4: 第1シート設計部第11シート設計室 | D4: 16113002 | F4: 9591 | G4: 320D | I4: 6月 | J4: 45078 | K4: 鈴木
A5: 完了 | B5: 2 | C5: 第1シート設計部第11シート設計室 | D5: 16113003 | F5: 9787 | G5: 320D | I5: 7月 | J5: 45103 | K5: 鈴木
A6: 進行中 | B6: 3 | C6: 第1シート設計部第11シート設計室 | D6: 16113004 | F6: 10172 | G6: 320D | I6: 8月 | J6: 45128 | K6: 鈴木
B7: 4 | D7: 16113005
B8: 5 | D8: 16113006
B9: 6 | D9: 16113007
B10: 7 | D10: 16113008
B11: 8 | D11: 16113009
B12: 9 | D12: 16113010
B13: 10 | D13: 16113011
B14: 11 | D14: 16113012
B15: 12 | D15: 16113013
B16: 13 | D16: 16113014

Sheet A12
A1: 2024年 | C1: エンジニアリングサービス部 見積書・請求書発行管理台帳 | H1: 見積書(税抜金額)
A2: 企業名： | C2: トヨタ紡織(株)
A3: タスク | B3: No | C3: 部署名 | D3: 見積/請求番号 | E3: 発注番号 | F3: 業務計画書No | G3: 案件名 | H3: 見積金額 | I3: 見積月 | J3: 発行日 | K3: 発行者 | L3: 備考
A4: 完了 | B4: 1 | C4: 第1シート設計部第12シート設計室 | D4: 16108162 | E4: 802-2212-0031-000 | F4: ITK08249 | G4: 330D | I4: 1月 | J4: 44923 | K4: 鈴木
A5: 完了 | B5: 2 | C5: 第1シート設計部第12シート設計室 | D5: 16108163 | E5: 802-2212-0032-000 | F5: ITK08248 | G5: 440D | I5: 1月 | J5: 44923 | K5: 鈴木
A6: 完了 | B6: 3 | C6: 第1シート設計部第12シート設計室 | D6: 16108164 | E6: 802-2212-0104-000 | F6: ITK08116 | G6: 460B | I6: 1月 | J6: 44923 | K6: 鈴木
A7: 完了 | B7: 4 | C7: 第1シート設計部第12シート設計室 | D7: 16108165 | E7: 802-2301-0027-000 | F7: 8515 | G7: 330D | I7: 2月 | J7: 44960 | K7: 鈴木
A8: 完了 | B8: 5 | C8: 第1シート設計部第12シート設計室 | D8: 16108166 | E8: 802-2301-0026-000 | F8: 8516 | G8: 440D | I8: 2月 | J8: 44965 | K8: 鈴木
A9: 完了 | B9: 6 | C9: 第1シート設計部第12シート設計室 | D9: 16108167 | E9: 802-2301-0021-000 | F9: 8564 | G9: 460B | I9: 2月 | J9: 44965 | K9: 鈴木
A10: 完了 | B10: 7 | C10: 第1シート設計部第12シート設計室 | D10: 16108168 | E10: 802-2301-0023-000 | F10: 8557 | G10: 440D追加 | I10: 2月 | J10: 44965 | K10: 鈴木
A11: 完了 | B11: 8 | C11: 第1シート設計部第12シート設計室 | D11: 16108169 | F11: 8750 | G11: 330D | I11: 3月 | J11: 44994 | K11: 鈴木
A12: 完了 | B12: 9 | C12: 第1シート設計部第12シート設計室 | D12: 16108170 | F12: 8751 | G12: 440D | I12: 3月 | J12: 44994 | K12: 鈴木
A13: 完了 | B13: 10 | C13: 第1シート設計部第12シート設計室 | D13: 16108171 | F13: 8807 | G13: 460B | I13: 3月 | J13: 44994 | K13: 鈴木
A14: 完了 | B14: 11 | C14: 第1シート設計部第12シート設計室 | D14: 16108172 | F14: 9021 | G14: 440D | I14: 4月 | J14: 45016 | K14: 鈴木
A15: 完了 | B15: 12 | C15: 第1シート設計部第12シート設計室 | D15: 16108173 | F15: 9133 | G15: B626(440D) | I15: 4月 | J15: 45019 | K15: 鈴木
A16: 完了 | B16: 13 | C16: 第1シート設計部第12シート設計室 | D16: 16108174 | F16: 9327 | G16: 440D | I16: 5月 | J16: 45044 | K16: 鈴木
A17: 完了 | B17: 14 | C17: 第1シート設計部第12シート設計室 | D17: 16108175 | F17: 9544 | G17: 440D | I17: 6月 | J17: 45078 | K17: 鈴木
A18: 完了 | B18: 15 | C18: 第1シート設計部第12シート設計室 | D18: 16108176 | F18: 9651 | G18: 440D | I18: 7月 | J18: 45105 | K18: 鈴木
A19: 完了 | B19: 16 | C19: 第1シート設計部第12シート設計室 | D19: 16108177 | F19: 10065 | G19: 440D 追加 | I19: 7月 | J19: 45119 | K19: 鈴木
A20: 完了 | B20: 17 | C20: 第1シート設計部第12シート設計室 | D20: 16108178 | F20: 10053 | G20: 440D | I20: 8月 | J20: 45128 | K20: 鈴木
A21: 完了 | B21: 18 | C21: 第1シート設計部第12シート設計室 | D21: 16108179 | F21: 10361 | G21: 440D | I21: 9月 | J21: 45148 | K21: 鈴木
A22: 完了 | B22: 19 | C22: 第1シート設計部第12シート設計室 | D22: 16108180 | F22: 10711 | G22: 440D | I22: 10月 | J22: 45198 | K22: 齊藤
... A24: 完了 | B24: 21 | C24: 第1シート設計部第12シート設計室 | D24: 16108182 | F24: 11332 | G24: 440D | I24: 12月 | J24: 45252 | K24: 齊藤
B25: 22 | C25: 第1シート設計部第12シート設計室 | D25: 16108183 | F25: ITK11621 | G25: 440D | I25: 1月 | J25: 45279 | K25: 齊藤
B26: 23 | C26: 第1シート設計部第12シート設計室 | D26: 16108184 | F26: 11871 | G26: 440D | I26: 2月 | J26: 45310 | K26: 齊藤
B27: 24 | C27: 第1シート設計部第12シート設計室 | D27: 16108185 | F27: 12017 | G27: 440D | I27: 3月 | J27: 45337 | K27: 齊藤
B28: 25 | C28: 第1シート設計部第12シート設計室 | D28: 16108186 | F28: ITK12247 | G28: 440D | I28: 4月 | J28: 45377 | K28: 齊藤
B29: 26 | C29: 第1シート設計部第12シート設計室 | D29: 16108187 | F29: ITK12248 | G29: 330D | I29: 4月 | J29: 45377 | K29: 齊藤
B30: 27 | C30: 第1シート設計部第12シート設計室 | D30: 16108188 | F30: ITK12620 | G30: 440Ｄ | I30: 5月 | J30: 45401 | K30: 齊藤
B31: 28 | C31: 第1シート設計部第12シート設計室 | D31: 16108189 | F31: ITK12621 | G31: 330D | I31: 5月 | J31: 45401 | K31: 齊藤
B32: 29 | C32: 第1シート設計部第12シート設計室 | D32: 16108190 | F32: ITK12871 | G32: 440Ｄ | I32: 6月 | J32: 45433 | K32: 齊藤
B33: 30 | C33: 第1シート設計部第12シート設計室 | D33: 16108191 | F33: ITK12858 | G33: 330D | I33: 6月 | J33: 45435 | K33: 齊藤
B34: 31 | C34: 第1シート設計部第12シート設計室 | D34: 16108192 | F34: 13198 | G34: 330D | I34: 7月 | J34: 45467 | K34: 齊藤
B35: 32 | C35: 第1シート設計部第12シート設計室 | D35: 16108193 | F35: 13199 | G35: 440Ｄ | I35: 7月 | J35: 45467 | K35: 齊藤
B36: 33 | C36: 第1シート設計部第12シート設計室 | D36: 16108194 | F36: 13581 | G36: 440Ｄ | I36: 8月 | J36: '24/7/16 | K36: 齊藤
B37: 34 | C37: 第1シート設計部第12シート設計室 | D37: 16108195 | F37: 13574 | G37: 330D | I37: 8月 | J37: '24/7/16 | K37: 齊藤
B38: 35 | C38: 第1シート設計部第12シート設計室 | D38: 16108196 | F38: 13773 | G38: 330D | I38: 9月 | J38: '24/8/21 | K38: 齊藤
B39: 36 | C39: 第1シート設計部第12シート設計室 | D39: 16108197 | F39: 13774 | G39: 440Ｄ | I39: 9月 | J39: '24/8/21 | K39: 齊藤
B40: 37 | C40: 第1シート設計部第12シート設計室 | D40: 16108198 | F40: 14089 | G40: 330D | I40: 10月 | J40: '24/10/3 | K40: 久目形
B41: 38 | C41: 第1シート設計部第12シート設計室 | D41: 16108199 | F41: 14088 | G41: 440Ｄ | I41: 10月 | J41: '24/10/3 | K41: 久目形
...

Sheet A13
A1: 2023年 | C1: エンジニアリングサービス部 見積書・請求書発行管理台帳 | H1: 見積書(税抜金額)
A2: 企業名： | C2: トヨタ紡織(株)
A3: タスク | B3: No | C3: 部署名 | D3: 見積/請求番号 | E3: 発注番号 | F3: 業務計画書No | G3: 案件名 | H3: 見積金額 | I3: 見積月 | J3: 発行日 | K3: 発行者 | L3: 備考
A4: 完了 | B4: 1 | C4: 第1シート設計部第13シート設計室 | D4: 16101111 | E4: 802-2212-0157-000 | F4: ITK08044 | G4: 759W | H4: 391300 | I4: 1月 | J4: 44923 | K4: 鈴木
A5: 完了 | B5: 2 | C5: 第1シート設計部第13シート設計室 | D5: 16101112 | E5: 802-2212-0092-000 | F5: ITK08147 | G5: 400BX | H5: 774000 | I5: 1月 | J5: 44923 | K5: 鈴木
A6: 完了 | B6: 3 | C6: 第1シート設計部第13シート設計室 | D6: 16101113 | E6: 802-2212-0089-000 | F6: ITK08151 | G6: 738W(400B)_VA | H6: 323000 | I6: 1月 | J6: 44923 | K6: 鈴木
A7: 完了 | B7: 4 | C7: 第1シート設計部第13シート設計室 | D7: 16101114 | E7: 802-2212-0091-000 | F7: ITK08148 | G7: 345D | H7: 119000 | I7: 1月 | J7: 44923 | K7: 鈴木
A8: 完了 | B8: 5 | C8: 第1シート設計部第13シート設計室 | D8: 16101115 | E8: 802-2212-0090-000 | F8: ITK08149 | G8: 346D | H8: 655000 | I8: 1月 | J8: 44923 | K8: 鈴木
A9: 完了 | B9: 6 | C9: 第1シート設計部第13シート設計室 | D9: 16101116 | E9: 802-2301-0063-000 | F9: 8444 | G9: 759W 号口 | H9: 240800 | I9: 2月 | J9: 44959 | K9: 鈴木
A10: 完了 | B10: 7 | C10: 第1シート設計部第13シート設計室 | D10: 16101117 | E10: 802-2301-0066-000 | F10: 8436 | G10: 400BX | H10: 774000 | I10: 2月 | J10: 44960 | K10: 鈴木
A11: 完了 | B11: 8 | C11: 第1シート設計部第13シート設計室 | D11: 16101118 | E11: 802-2301-0059-000 | F11: 8449 | G11: 400B VA | H11: 512000 | I11: 2月 | J11: 44960 | K11: 鈴木
A12: 完了 | B12: 9 | C12: 第1シート設計部第13シート設計室 | D12: 16101119 | E12: 802-2301-0065-000 | F12: 8437 | G12: 345D | H12: 807000 | I12: 2月 | J12: 44960 | K12: 鈴木
A13: 完了 | B13: 10 | C13: 第1シート設計部第13シート設計室 | D13: 16101120 | E13: 802-2302-0091-000 | F13: 8651 | G13: 759W 号口 | H13: 365500 | I13: 3月 | J13: 44984 | K13: 鈴木
A14: 完了 | B14: 11 | C14: 第1シート設計部第13シート設計室 | D14: 16101121 | F14: 8766 | G14: 400BX | H14: 774000 | I14: 3月 | J14: 44994 | K14: 鈴木
A15: 完了 | B15: 12 | C15: 第1シート設計部第13シート設計室 | D15: 16101122 | F15: 8765 | G15: 400B VA | H15: 525000 | I15: 3月 | J15: 44994 | K15: 鈴木

Sheet A2
A1: 2023年 | C1: エンジニアリングサービス部 見積書・請求書発行管理台帳 | H1: 見積書(税抜金額)
A2: 企業名： | C2: トヨタ紡織(株)
A3: タスク | B3: No | C3: 部署名 | D3: 見積/請求番号 | E3: 発注番号 | F3: 業務計画書No | G3: 案件名 | H3: 見積金額 | I3: 見積月 | J3: 発行日 | K3: 発行者 | L3: 備考
C4: 第2シート設計部 | D4: 16106002

Sheet A3
A1: 2024年 | C1: エンジニアリングサービス部 見積書・請求書発行管理台帳 | H1: 見積書(税抜金額)
A2: 企業名： | C2: トヨタ紡織(株)
A3: タスク | B3: No | C3: 部署名 | D3: 見積/請求番号 | E3: 発注番号 | F3: 業務計画書No | G3: 案件名 | H3: 見積金額 | I3: 見積月 | J3: 発行日 | K3: 発行者 | L3: 備考
A4: 完了 | B4: 1 | C4: 第3シート設計部 | D4: 16107028 | E4: A31-R7454 | F4: - | G4: 無償修理低減解析 | I4: 1月 | J4: 44903 | K4: 鈴木
A5: 完了 | B5: 2 | C5: 第3シート設計部第32シート設計室 | D5: 16107033 | E5: 802-2212-0191-000 | F5: ITK08002 | G5: 277D | I5: 1月 | J5: 44923 | K5: 鈴木
A6: 完了 | B6: 3 | C6: 第3シート設計部第32シート設計室 | D6: 16107034 | E6: 802-2212-0190-000 | F6: ITK08004 | G6: 492D | I6: 1月 | J6: 44923 | K6: 鈴木
A7: 完了 | B7: 4 | C7: 第3シート設計部第32シート設計室 | D7: 16107035 | E7: 802-2212-0187-000 | F7: ITK08009 | G7: 493D | I7: 1月 | J7: 44923 | K7: 鈴木
A8: 完了 | B8: 5 | C8: 第3シート設計部第32シート設計室 | D8: 16107036 | E8: 802-2212-0192-000 | F8: ITK08001 | G8: 825B | I8: 1月 | J8: 44923 | K8: 鈴木
A9: 完了 | B9: 6 | C9: 第3シート設計部第32シート設計室 | D9: 16107037 | E9: 802-2212-0052-000 | F9: ITK08209 | G9: 018D | I9: 1月 | J9: 44923 | K9: 鈴木
A10: 完了 | B10: 7 | C10: 第3シート設計部 | D10: 16107038 | E10: A31-R7455 | F10: - | G10: 無償修理低減解析 | I10: 2月 | J10: 44937 | K10: 鈴木
A11: 完了 | B11: 8 | C11: 第3シート設計部第32シート設計室 | D11: 16107039 | E11: 802-2301-0139-000 | F11: 8295 | G11: 277D | I11: 2月 | J11: 44965 | K11: 鈴木
A12: 完了 | B12: 9 | C12: 第3シート設計部第32シート設計室 | D12: 16107040 | E12: 802-2301-0111-000 | F12: 8366 | G12: 492D | I12: 2月 | J12: 44965 | K12: 鈴木
A13: 完了 | B13: 10 | C13: 第3シート設計部第32シート設計室 | D13: 16107041 | E13: 802-2301-0107-000 | F13: 8370 | G13: 493D | I13: 2月 | J13: 44965 | K13: 鈴木
A14: 完了 | B14: 11 | C14: 第3シート設計部第32シート設計室 | D14: 16107042 | E14: 802-2301-0141-000 | F14: 8293 | G14: 825B | I14: 2月 | J14: 44965 | K14: 鈴木
A15: 完了 | B15: 12 | C15: 第3シート設計部第32シート設計室 | D15: 16107043 | E15: 802-2301-0140-000 | F15: 8294 | G15: 018D | I15: 2月 | J15: 44965 | K15: 鈴木
A16: 完了 | B16: 13 | C16: 第3シート設計部第32シート設計室 | D16: 16107044 | E16: 802-2302-0117-000 | F16: 8606 | G16: 277D | I16: 3月 | J16: 44984 | K16: 鈴木
A17: 完了 | B17: 14 | C17: 第3シート設計部第32シート設計室 | D17: 16107045 | F17: 8608 | G17: 492D | I17: 3月 | J17: 44986 | K17: 鈴木
A18: 完了 | B18: 15 | C18: 第3シート設計部第32シート設計室 | D18: 16107046 | F18: 8610 | G18: 493D | I18: 3月 | J18: 44986 | K18: 鈴木
A19: 完了 | B19: 16 | C19: 第3シート設計部第32シート設計室 | D19: 16107047 | E19: 802-2302-0119-000 | F19: 8604 | G19: 825B | I19: 3月 | J19: 44984 | K19: 鈴木
A20: 完了 | B20: 17 | C20: 第3シート設計部第32シート設計室 | D20: 16107048 | E20: 802-2302-0118-000 | F20: 8605 | G20: 018D | I20: 3月 | J20: 44984 | K20: 鈴木
A21: 完了 | B21: 18 | C21: 第3シート設計部 | D21: 16107049 | F21: - | G21: 無償修理低減解析 | I21: 3月 | J21: 44966 | K21: 鈴木
A22: 完了 | B22: 19 | C22: 第3シート設計部 | D22: 16107050 | F22: - | G22: 無償修理低減解析 | I22: 4月 | J22: 44999 | K22: 鈴木
A23: 完了 | B23: 20 | C23: 第3シート設計部 | D23: 16107051 | F23: - | G23: 無償修理低減解析 | I23: 5月 | J23: 45023 | K23: 鈴木
A24: 完了 | B24: 21 | C24: 第3シート設計部 | D24: 16107052 | F24: - | G24: 無償修理低減解析 | I24: 6月 | J24: 45063 | K24: 鈴木
A25: 完了 | B25: 22 | C25: 第3シート設計部 | D25: 16107053 | F25: - | G25: 無償修理低減解析 | I25: 7月 | J25: 45085 | K25: 鈴木
A26: 完了 | B26: 23 | C26: 第3シート設計部 | D26: 16107054 | F26: - | G26: 無償修理低減解析 | I26: 8月 | J26: 45112 | K26: 鈴木
A27: 完了 | B27: 24 | C27: 第3シート設計部 | D27: 16107055 | F27: - | G27: 無償修理低減解析 | I27: 9月 | J27: 45148 | K27: 鈴木
A28: 完了 | B28: 25 | C28: 第3シート設計部 | D28: 16107056 | F28: - | G28: 無償修理低減解析 | I28: 10月 | J28: 45183 | K28: 齊藤
A29: 完了 | B29: 26 | C29: 第3シート設計部 | D29: 16107057 | F29: - | G29: 無償修理低減解析 | I29: 11月 | J29: 45210 | K29: 齊藤
A30: 完了 | B30: 27 | C30: 第3シート設計部 | D30: 16107058 | F30: - | G30: 無償修理低減解析 | I30: 12月 | J30: 45243 | K30: 齊藤
B31: 28 | C31: 第3シート設計部 | D31: 16107059 | F31: - | G31: 無償修理低減解析 | I31: 1月 | J31: 45266 | K31: 齊藤
B32: 29 | C32: 第3シート設計部 | D32: 16107060 | F32: ITK11502 | G32: 650D | I32: 1月 | J32: 45275 | K32: 齊藤
B33: 30 | C33: 第3シート設計部 | D33: 16107061 | F33: - | G33: 無償修理低減解析 | I33: 2月 | J33: 45309 | K33: 齊藤
B34: 31 | C34: 第3シート設計部 | D34: 16107062 | F34: 11801 | G34: 650D | I34: 2月 | J34: 45309 | K34: 齊藤
B35: 32 | C35: 第3シート設計部 | D35: 16107063 | F35: - | G35: 無償修理低減解析 | I35: 3月 | J35: 45328 | K35: 齊藤
B36: 33 | C36: 第3シート設計部 | D36: 16107064 | F36: 12166 | G36: 650D | I36: 3月 | J36: 45341 | K36: 齊藤
B37: 34 | C37: 第3シート設計部 | D37: 16107065 | F37: - | G37: 無償修理低減解析 | I37: 4月 | J37: 45364 | K37: 齊藤
B38: 35 | C38: 第3シート設計部 | D38: 16107066 | F38: ITK12303 | G38: 650D | I38: 4月 | J38: 45377 | K38: 齊藤
B39: 36 | C39: 第3シート設計部 | D39: 16107067 | F39: ITK12409 | G39: 410D | I39: 4月 | J39: 45377 | K39: 齊藤
B40: 37 | C40: 第3シート設計部 | D40: 16107068 | F40: ITK12423 | G40: 450D | I40: 4月 | J40: 45377 | K40: 齊藤
...

Sheet A4
A1: 2024年 | C1: エンジニアリングサービス部 見積書・請求書発行管理台帳 | H1: 見積書(税抜金額)
A2: 企業名： | C2: トヨタ紡織(株)
A3: タスク | B3: No | C3: 部署名 | D3: 見積/請求番号 | E3: 発注番号 | F3: 業務計画書No | G3: 案件名 | H3: 見積金額 | I3: 見積月 | J3: 発行日 | K3: 発行者 | L3: 備考
B4: 1 | C4: 第4シート設計部 | D4: 16123001 | E4: A31-R7454 | F4: ITK12712 | G4: QA08 TB3 | I4: 5月 | J4: 45401 | K4: 齊藤
B5: 2 | C5: 第4シート設計部 | D5: 16123002 | E5: 802-2212-0191-000 | F5: ITK12730 | G5: 410D TB3 | I5: 5月 | J5: 45401 | K5: 齊藤
B6: 3 | C6: 第4シート設計部 | D6: 16123003 | E6: 802-2212-0190-000 | F6: ITK12731 | G6: 450D TB3 | I6: 5月 | J6: 45401 | K6: 齊藤
B7: 4 | C7: 第4シート設計部 | D7: 16123004 | E7: 802-2212-0187-000 | F7: ITK12887 | G7: 410D TB3 | I7: 6月 | J7: 45433 | K7: 齊藤
B8: 5 | C8: 第4シート設計部 | D8: 16123005 | E8: 802-2212-0192-000 | F8: ITK12889 | G8: 450D TB3 | I8: 6月 | J8: 45433 | K8: 齊藤
B9: 6 | C9: 第4シート設計部 | D9: 16123006 | E9: 802-2212-0052-000 | F9: ITK12807 | G9: QA08 TB3 | I9: 6月 | J9: 45435 | K9: 齊藤
B10: 7 | C10: 第4シート設計部 | D10: 16123007 | E10: A31-R7455 | F10: 13144 | G10: 410D TB3 | I10: 7月 | J10: 45467 | K10: 齊藤
B11: 8 | C11: 第4シート設計部 | D11: 16123008 | E11: 802-2301-0139-000 | F11: 13146 | G11: QA08 TB3 | I11: 7月 | J11: 45467 | K11: 齊藤
B12: 9 | C12: 第4シート設計部 | D12: 16123009 | E12: 802-2301-0111-000 | F12: 13145 | G12: 450D TB3 | I12: 7月 | J12: 45467 | K12: 齊藤
B13: 10 | C13: 第4シート設計部 | D13: 16123010 | E13: 802-2301-0107-000 | F13: 13496 | G13: 450D TB3 | I13: 8月 | J13: '24/7/16 | K13: 齊藤
B14: 11 | C14: 第4シート設計部 | D14: 16123011 | E14: 802-2301-0141-000 | F14: 13495 | G14: 410D TB3 | I14: 8月 | J14: '24/7/18 | K14: 齊藤
B15: 12 | C15: 第4シート設計部 | D15: 16123012 | E15: 802-2301-0140-000 | F15: 13384 | G15: QA08 TB3 | I15: 8月 | J15: '24/7/22 | K15: 齊藤
B16: 13 | C16: 第4シート設計部 | D16: 16123013 | E16: 802-2302-0117-000 | F16: 13603 | G16: QA08 TB3 | I16: 9月 | J16: '24/8/21 | K16: 齊藤
B17: 14 | C17: 第4シート設計部 | D17: 16123014 | F17: 13763 | G17: 450D TB3 | I17: 9月 | J17: '24/8/21 | K17: 齊藤
B18: 15 | C18: 第4シート設計部 | D18: 16123015 | F18: 13762 | G18: 410D TB3 | I18: 9月 | J18: '24/8/21 | K18: 齊藤
B19: 16 | C19: 第4シート設計部 | D19: 16123016 | E19: 802-2302-0119-000 | F19: 13934 | G19: 450D TB3 | I19: 10月 | J19: '24/10/3 | K19: 久目形
B20: 17 | C20: 第4シート設計部 | D20: 16123017 | E20: 802-2302-0118-000 | F20: 13933 | G20: 410D TB3 | I20: 10月 | J20: '24/10/3 | K20: 久目形
B21: 18 | C21: 第4シート設計部 | D21: 16123018 | F21: 13890 | G21: QA08 TB3 | I21: 10月 | J21: '24/10/3 | K21: 久目形
B22: 19 | C22: 第4シート設計部 | D22: 16123019 | F22: 14245 | G22: 410D TB3 | I22: 11月 | J22: '24/11/1 | K22: 久目形
B23: 20 | C23: 第4シート設計部 | D23: 16123020 | F23: 14244 | G23: 450D TB3 | I23: 11月 | J23: '24/11/1 | K23: 久目形
B24: 21 | C24: 第4シート設計部 | D24: 16123021 | F24: 14196 | G24: QA08 TB3 | I24: 11月 | J24: '24/11/1 | K24: 久目形
B25: 22 | C25: 第4シート設計部 | D25: 16123022 | F25: 14421 | G25: QA08 TB3 | I25: 12月 | J25: '24/11/29 | K25: 久目形
B26: 23 | C26: 第4シート設計部 | D26: 16123023 | F26: 14432 | G26: 410D TB3 | I26: 12月 | J26: '24/11/29 | K26: 久目形
B27: 24 | C27: 第4シート設計部 | D27: 16123024 | F27: 14433 | G27: 450D TB3 | I27: 12月 | J27: '24/11/29 | K27: 久目形
B28: 25 | C28: 第4シート設計部 | D28: 16123025 | F28: 14681 | G28: QA08 TB3 | I28: 1月 | J28: 45645 | K28: 久目形
B29: 26 | C29: 第4シート設計部 | D29: 16123026 | F29: 14695 | G29: 410D TB3 | I29: 1月 | J29: 45645 | K29: 久目形
B30: 27 | C30: 第4シート設計部 | D30: 16123027 | F30: 14696 | G30: 450D TB3 | I30: 1月 | J30: 45645 | K30: 久目形
B31: 28 | C31: 第4シート設計部 | D31: 16123028 | F31: 14936 | G31: QA08 TB3 | I31: 2月 | J31: 202/2/29 | K31: 久目形
B32: 29 | C32: 第4シート設計部 | D32: 16123029 | F32: 14973 | G32: 410D TB3 | I32: 2月 | J32: 202/2/29 | K32: 久目形
B33: 30 | C33: 第4シート設計部 | D33: 16123030 | F33: 14974 | G33: 450D TB3 | I33: 2月 | J33: 202/2/29 | K33: 久目形
B34: 31 | C34: 第4シート設計部 | D34: 16123031 | F34: 15214 | G34: QA08 TB3 | I34: 3月 | J34: 2025/2/26 | K34: 久目形
B35: 32 | C35: 第4シート設計部 | D35: 16123032 | F35: 15254 | G35: 410D TB3 | I35: 3月 | J35: 2025/2/26 | K35: 久目形
B36: 33 | C36: 第4シート設計部 | D36: 16123033 | F36: 15255 | G36: 450D TB3 | I36: 3月 | J36: 2025/2/26 | K36: 久目形
B37: 34 | C37: 第4シート設計部 | D37: 16123034 | F37: ITK15483 | G37: 32AT TB3 | I37: 4月 | J37: 45744 | K37: 丸山
B38: 35 | C38: 第4シート設計部 | D38: 16123035 | F38: ITK15846 | G38: 32AT TB3 | I38: 5月 | J38: 45784 | K38: 丸山
B39: 36 | C39: 第4シート設計部 | D39: 16123036 | F39: 16076 | G39: 32AT TB3 | I39: 6月 | J39: 45805 | K39: 丸山
B40: 37 | C40: 第4シート設計部 | D40: 16123037 | F40: 16329 | G40: 32AT TB3 | I40: 7月 | J40: 45835 | K40: 久目形
...

Sheet Fr骨格
A1: 2024年 | C1: エンジニアリングサービス部 見積書・請求書発行管理台帳 | H1: 見積書(税抜金額)
A2: 企業名： | C2: トヨタ紡織(株)
A3: タスク | B3: No | C3: 部署名 | D3: 見積/請求番号 | E3: 発注番号 | F3: 業務計画書No | G3: 案件名 | H3: 見積金額 | I3: 見積月 | J3: 発行日 | K3: 発行者 | L3: 備考
A4: 完了 | B4: 1 | C4: Frシート骨格設計部第2設計室 | D4: 16102047 | E4: 802-2212-0086-000 | F4: ITk08154 | G4: TNGA/SK7 FRシート骨格 | I4: 1月 | J4: 44923 | K4: 鈴木
A5: 完了 | B5: 2 | C5: Frシート骨格設計部第2設計室 | D5: 16102048 | E5: 802-2212-0085-000 | F5: ITK08160 | G5: SK7 FRシート骨格 | I5: 1月 | J5: 44923 | K5: 鈴木
A6: 完了 | B6: 3 | C6: Frシート骨格設計部第2設計室 | D6: 16102049 | E6: 802-2301-0002-000 | F6: 8443 | G6: 410D | I6: 1月 | J6: 44937 | K6: 鈴木
A7: 完了 | B7: 4 | C7: Frシート骨格設計部第2設計室 | D7: 16102050 | E7: 802-2301-0055-000 | F7: 8459 | G7: TNGA/SK7 FRシート骨格 | I7: 2月 | J7: 44960 | K7: 鈴木
A8: 完了 | B8: 5 | C8: Frシート骨格設計部第2設計室 | D8: 16102051 | E8: 802-2301-0044-000 | F8: 8476 | G8: SK7 FRシート骨格 | I8: 2月 | J8: 44960 | K8: 鈴木
A9: 完了 | B9: 6 | C9: Frシート骨格設計部第2設計室 | D9: 16102052 | E9: 802-2301-0041-000 | F9: 8479 | G9: 410D | I9: 2月 | J9: 44960 | K9: 鈴木
A10: 完了 | B10: 7 | C10: Frシート骨格設計部第2設計室 | D10: 16102053 | F10: 8655 | G10: TNGA/SK7 FRシート骨格 | I10: 3月 | J10: 44994 | K10: 鈴木
A11: 完了 | B11: 8 | C11: Frシート骨格設計部第2設計室 | D11: 16102054 | F11: 8690 | G11: SK7 FRシート骨格 | I11: 3月 | J11: 44994 | K11: 鈴木
A12: 完了 | B12: 9 | C12: Frシート骨格設計部第2設計室 | D12: 16102055 | F12: 8693 | G12: 502D | I12: 2月 | J12: 44994 | K12: 鈴木
A13: 完了 | B13: 10 | C13: Frシート骨格設計部第2設計室 | D13: 16102056 | F13: 8749 | G13: 502D | I13: 3月 | J13: 44994 | K13: 鈴木
A14: 完了 | B14: 11 | C14: Frシート骨格設計部第2設計室 | D14: 16102057 | F14: 8945 | G14: TNGA/SK7 FRシート骨格 | I14: 4月 | J14: 45023 | K14: 鈴木
A15: 完了 | B15: 12 | C15: Frシート骨格設計部第2設計室 | D15: 16102058 | F15: 9337 | G15: TNGA/SK7 FRシート骨格 | I15: 5月 | J15: 45044 | K15: 鈴木
A16: 完了 | B16: 13 | C16: Frシート骨格設計部第2設計室 | D16: 16102059 | F16: 9549 | G16: TNGA/SK7 FRシート骨格 | I16: 6月 | J16: 45078 | K16: 鈴木
A17: 完了 | B17: 14 | C17: Frシート骨格設計部第2設計室 | D17: 16102060 | F17: 9704 | G17: X1T5 次世代バックフレーム | I17: 6月 | J17: 45090 | K17: 鈴木
A18: 完了 | B18: 15 | C18: Frシート骨格設計部第2設計室 | D18: 16102061 | F18: 9792 | G18: TNGA/SK7 FRシート骨格 | I18: 7月 | J18: 45103 | K18: 鈴木
A19: 完了 | B19: 16 | C19: Frシート骨格設計部第2設計室 | D19: 16102062 | F19: 9732 | G19: X1T5 次世代バックフレーム | I19: 7月 | J19: 45103 | K19: 鈴木
A20: 完了 | B20: 17 | C20: Frシート骨格設計部第2設計室 | D20: 16102063 | F20: 10141 | G20: X1T5 次世代バックフレーム | I20: 8月 | J20: 45128 | K20: 鈴木
A21: 完了 | B21: 18 | C21: Frシート骨格設計部第2設計室 | D21: 16102064 | F21: 10150 | G21: TNGA/SK7 FRシート骨格 | I21: 8月 | J21: 45128 | K21: 鈴木
... A35: 完了 | B35: 32 | C35: Frシート骨格設計部第2設計室 | D35: 16102078 | F35: 11356 | G35: SUBARU 28BEV RFQ対応 | I35: 12月 | J35: 45257 | K35: 齊藤
A36: 完了 | B36: 33 | C36: Frシート骨格設計部第2設計室 | D36: 16102079 | F36: ITK11355 | G36: 581D Frシート骨格開発 | I36: 12月 | J36: 45264 | K36: 齊藤
B37: 34 | C37: Frシート骨格設計部第2設計室 | D37: 16102080 | F37: 11615 | G37: TNGA/SK7 FRシート骨格 | I37: １月 | J37: 45279 | K37: 齊藤
B38: 35 | C38: Frシート骨格設計部第2設計室 | D38: 16102081 | F38: ITK11614 | G38: 581D Frシート骨格開発 | I38: １月 | J38: 45279 | K38: 齊藤
B39: 36 | C39: Frシート骨格設計部第2設計室 | D39: 16102082 | F39: 11759 | G39: TNGA/SK7 FRシート骨格 | I39: 2月 | J39: 45310 | K39: 齊藤
B40: 37 | C40: Frシート骨格設計部第2設計室 | D40: 16102083 | F40: 11764 | G40: X1T8 他社販骨格開 | I40: 2月 | J40: 45310 | K40: 齊藤
B41: 38 | C41: Frシート骨格設計部第2設計室 | D41: 16102084 | F41: 11794 | G41: 581D Frシート骨格開発 | I41: 2月 | J41: 45310 | K41: 齊藤
B42: 39 | C42: Frシート骨格設計部第2設計室 | D42: 16102085 | F42: 11866 | G42: 500DFrシート骨格開発 | I42: 2月 | J42: 45310 | K42: 齊藤
B43: 40 | C43: Frシート骨格設計部第2設計室 | D43: 16102086 | F43: 11880 | G43: X1T5 次世代バックフレーム | I43: 2月 | J43: 45310 | K43: 齊藤
B44: 41 | C44: Frシート骨格設計部第2設計室 | D44: 16102087 | F44: 12052 | G44: TNGA/SK7 FRシート骨格 | I44: 3月 | J44: 45337 | K44: 齊藤
B45: 42 | C45: Frシート骨格設計部第2設計室 | D45: 16102088 | F45: 12090 | G45: 581D Frシート骨格開発 | I45: 3月 | J45: 45337 | K45: 齊藤
B46: 43 | C46: Frシート骨格設計部第2設計室 | D46: 16102089 | F46: 12061 | G46: X1T5 次世代バックフレーム | I46: 3月 | J46: 45337 | K46: 齊藤
B47: 44 | C47: Frシート骨格設計部第2設計室 | D47: 16102090 | F47: 12130 | G47: 500DFrシート骨格開発 | I47: 3月 | J47: 45337 | K47: 齊藤
B48: 45 | C48: Frシート骨格設計部第2設計室 | D48: 16102091 | F48: 12046 | G48: X1T8 他社販骨格開 | I48: 3月 | J48: 45345 | K48: 齊藤
B49: 46 | C49: Frシート骨格設計部骨格開発室 | D49: 16102092 | F49: ITK12318 | G49: STEP3薄型PWRクッションフレーム | I49: 4月 | J49: 45377 | K49: 齊藤
B50: 47 | C50: Frシート骨格設計部第2設計室 | D50: 16102093 | F50: ITK12443 | G50: TNGA/SK7 FRシート骨格 | I50: 4月 | J50: 45377 | K50: 齊藤
B51: 48 | C51: Frシート骨格設計部第1設計室 | D51: 16102094 | F51: ITK12468 | G51: 2.5巡目車種展 | I51: 4月 | J51: 45377 | K51: 齊藤
B52: 49 | C52: Frシート骨格設計部第2設計室 | D52: 16102095 | F52: ITK12689 | G52: TNGA/SK7 FRシート骨格 | I52: 5月 | J52: 45401 | K52: 齊藤
B53: 50 | C53: Frシート骨格設計部骨格開発室 | D53: 16102096 | F53: ITK12696 | G53: STEP3薄型PWRクッションフレーム | I53: 5月 | J53: 45401 | K53: 齊藤
...

Sheet Rr骨格
A1: 2024年 | C1: エンジニアリングサービス部 見積書・請求書発行管理台帳 | H1: 見積書(税抜金額)
A2: 企業名： | C2: トヨタ紡織(株)
A3: タスク | B3: No | C3: 部署名 | D3: 見積/請求番号 | E3: 発注番号 | F3: 業務計画書No | G3: 案件名 | H3: 見積金額 | I3: 見積月 | J3: 発行日 | K3: 発行者 | L3: 備考
A4: 完了 | B4: 1 | C4: Rrシート骨格設計部第1設計室 | D4: 16104060 | E4: 802-2212-0147-000 | F4: ITK08061 | G4: ミニバン統合骨格 | I4: 1月 | J4: 44923 | K4: 鈴木
A5: 完了 | B5: 2 | C5: Rrシート骨格設計部第2設計室 | D5: 16104061 | E5: 802-2212-0079-000 | F5: ITK08166 | G5: 440D | I5: 1月 | J5: 44923 | K5: 鈴木
A6: 完了 | B6: 3 | C6: Rrシート骨格設計部第1設計室 | D6: 16104062 | E6: 802-2301-0070-000 | F6: 8431 | G6: ミニバン統合骨格 | I6: 2月 | J6: 44965 | K6: 鈴木
A7: 完了 | B7: 4 | C7: Rrシート骨格設計部第2設計室 | D7: 16104063 | E7: 802-2301-0071-000 | F7: 8430 | G7: 440D | I7: 2月 | J7: 44965 | K7: 鈴木
A8: 完了 | B8: 5 | C8: Rrシート骨格設計部第2設計室 | D8: 16104064 | E8: 802-2302-0082-000 | F8: 8662 | G8: 440D | I8: 3月 | J8: 44986 | K8: 鈴木
A9: 完了 | B9: 6 | C9: Rrシート骨格設計部第1設計室 | D9: 16104065 | E9: 802-2302-0058-000 | F9: 8707 | G9: ミニバン統合骨格 | I9: 3月 | J9: 44986 | K9: 鈴木
A10: 完了 | B10: 7 | C10: Rrシート骨格設計部第2設計室 | D10: 16104066 | F10: 8851 | G10: SUBARU | I10: 3月 | J10: 44994 | K10: 鈴木
A11: 完了 | B11: 8 | C11: Rrシート骨格設計部第1設計室 | D11: 16104067 | F11: 8858 | G11: ミニバン統合骨格 | I11: 4月 | J11: 45016 | K11: 鈴木
A12: 完了 | B12: 9 | C12: Rrシート骨格設計部第1設計室 | D12: 16104068 | F12: 9173 | G12: ミニバン統合骨格 | I12: 5月 | J12: 45044 | K12: 鈴木
A13: 完了 | B13: 10 | C13: Rrシート骨格設計部第1設計室 | D13: 16104069 | F13: 9442 | G13: ミニバン統合骨格 | I13: 6月 | J13: 45078 | K13: 鈴木
A14: 完了 | B14: 11 | C14: Rrシート骨格設計部第1設計室 | D14: 16104070 | F14: 9732 | G14: ミニバン統合骨格 | I14: 7月 | J14: 45105 | K14: 鈴木
A15: 完了 | B15: 12 | C15: Rrシート骨格設計部第1設計室 | D15: 16104071 | F15: 10100 | G15: ミニバン統合骨格 | I15: 8月 | J15: 45128 | K15: 鈴木
A16: 完了 | B16: 13 | C16: Rrシート骨格設計部第2設計室 | D16: 16104072 | F16: 10243 | G16: QE36 SUBARU | I16: 8月 | J16: 45141 | K16: 鈴木
A17: 完了 | B17: 14 | C17: Rrシート骨格設計部第2設計室 | D17: 16104073 | F17: 10325 | G17: B658 SUBARU | I17: 8月 | J17: 45141 | K17: 鈴木
A18: 完了 | B18: 15 | C18: Rrシート骨格設計部第1設計室 | D18: 16104074 | F18: 10410 | G18: ミニバン統合骨格 | I18: 9月 | J18: 45148 | K18: 鈴木
A19: 完了 | B19: 16 | C19: Rrシート骨格設計部第2設計室 | D19: 16104075 | F19: 10404 | G19: QE36 SUBARU | I19: 9月 | J19: 45148 | K19: 鈴木
A20: 完了 | B20: 17 | C20: Rrシート骨格設計部第2設計室 | D20: 16104076 | F20: 10405 | G20: B658 SUBARU | I20: 9月 | J20: 45148 | K20: 鈴木
A21: 完了 | B21: 18 | C21: Rrシート骨格設計部第2設計室 | D21: 16104077 | F21: 10449 | G21: 410D | I21: 8月 | J21: 45160 | K21: 鈴木
A22: 完了 | B22: 19 | C22: Rrシート骨格設計部第2設計室 | D22: 16104078 | F22: ITK10742 | G22: 351D台座FRM開発 | I22: 9月 | J22: 45188 | K22: 齊藤
A23: 完了 | B23: 20 | C23: Rrシート骨格設計部第2設計室 | D23: 16104079 | F23: 10582 | G23: ミニバン統合骨格 | I23: 10月 | J23: 45198 | K23: 齊藤
A24: 完了 | B24: 21 | C24: Rrシート骨格設計部第2設計室 | D24: 16104080 | F24: 10565 | G24: QE36 SUBARU | I24: 10月 | J24: 45198 | K24: 齊藤
A25: 完了 | B25: 22 | C25: Rrシート骨格設計部第2設計室 | D25: 16104081 | F25: 10564 | G25: B658 SUBARU | I25: 10月 | J25: 45198 | K25: 齊藤
A26: 進行中 | B26: 23 | C26: Rrシート骨格設計部第2設計室 | D26: 16104082 | F26: 10990 | G26: QE36 SUBARU | I26: 11月 | J26: 45225 | K26: 齊藤
A27: 進行中 | B27: 24 | C27: Rrシート骨格設計部第2設計室 | D27: 16104083 | F27: 10984 | G27: ミニバン統合骨格 | I27: 11月 | J27: 45225 | K27: 齊藤
A28: 進行中 | B28: 25 | C28: Rrシート骨格設計部第2設計室 | D28: 16104084 | F28: 10982 | G28: B658 SUBARU | I28: 11月 | J28: 45225 | K28: 齊藤
B29: 26 | C29: Rrシート骨格設計部第2設計室 | D29: 16104085 | F29: 11330 | G29: 410D | I29: 11月 | J29: 45257 | K29: 齊藤
B30: 27 | C30: Rrシート骨格設計部第3設計室 | D30: 16104086 | F30: 11197 | G30: ミニバン統合骨格 | I30: 12月 | J30: 45250 | K30: 齊藤
B31: 28 | C31: Rrシート骨格設計部第4設計室 | D31: 16104087 | F31: 11192 | G31: B658 SUBARU | I31: 12月 | J31: 45250 | K31: 齊藤
B32: 29 | C32: Rrシート骨格設計部第5設計室 | D32: 16104088 | F32: 11191 | G32: QE36 SUBARU | I32: 12月 | J32: 45250 | K32: 齊藤
B33: 30 | C33: Rrシート骨格設計部第2設計室 | D33: 16104089 | F33: 11584 | G33: ミニバン統合骨格 | I33: 1月 | J33: 45279 | K33: 齊藤
B34: 31 | C34: Rrシート骨格設計部第2設計室 | D34: 16104090 | F34: 11581 | G34: B658 SUBARU | I34: 1月 | J34: 45279 | K34: 齊藤
B35: 32 | C35: Rrシート骨格設計部第2設計室 | D35: 16104091 | F35: 11580 | G35: QE36 SUBARU | I35: 1月 | J35: 45279 | K35: 齊藤
B36: 33 | C36: Rrシート骨格設計部第2設計室 | D36: 16104092 | F36: 11805 | G36: QE36 SUBARU | I36: 2月 | J36: 45309 | K36: 齊藤
B37: 34 | C37: Rrシート骨格設計部第2設計室 | D37: 16104093 | F37: 11806 | G37: B658 SUBARU | I37: 2月 | J37: 45309 | K37: 齊藤
B38: 35 | C38: Rrシート骨格設計部第2設計室 | D38: 16104094 | F38: 11807 | G38: ミニバン統合骨格 | I38: ２月 | J38: 45279 | K38: 齊藤
B39: 36 | C39: Rrシート骨格設計部第2設計室 | D39: 16104095 | F39: 12099 | G39: B658 SUBARU | I39: 3月 | J39: 45337 | K39: 齊藤
B40: 37 | C40: Rrシート骨格設計部第2設計室 | D40: 16104096 | F40: 12098 | G40: QE36 SUBARU | I40: 3月 | J40: 45337 | K40: 齊藤
...

Sheet GS
A1: 2024年 | C1: エンジニアリングサービス部 見積書・請求書発行管理台帳 | H1: 見積書(税抜金額)
A2: 企業名： | C2: トヨタ紡織(株)
A3: タスク | B3: No | C3: 部署名 | D3: 見積/請求番号 | E3: 発注番号 | F3: 業務計画書No | G3: 案件名 | H3: 見積金額 | I3: 見積月 | J3: 発行日 | K3: 発行者 | L3: 備考
A4: 完了 | B4: 1 | C4: グローバルシート設計室 | D4: 16119078 | E4: 802-2212-0158-000 | F4: ITK08043 | G4: D92A/D54B | I4: 1月 | J4: 44923 | K4: 鈴木
A5: 完了 | B5: 2 | C5: グローバルシート設計室 | D5: 16119079 | E5: 802-2212-0062-000 | F5: ITK08195 | G5: B-SUV 2列 | I5: 1月 | J5: 44923 | K5: 鈴木
A6: 完了 | B6: 3 | C6: グローバルシート設計室 | D6: 16119080 | E6: 802-2212-0199-000 | F6: ITK07918 | G6: B-SUV Fr開発 MY(追加) | I6: 1月 | J6: 44923 | K6: 鈴木
A7: 完了 | B7: 4 | C7: グローバルシート設計室 | D7: 16119081 | E7: 802-2212-0057-000 | F7: ITK08201 | G7: B-SUV Fr開発 MY | I7: 1月 | J7: 44923 | K7: 鈴木
A8: 完了 | B8: 5 | C8: グローバルシート設計室 | D8: 16119082 | E8: 802-2212-0193-000 | F8: ITK08000 | G8: 3列 B-EV | I8: 1月 | J8: 44923 | K8: 鈴木
A9: 完了 | B9: 6 | C9: グローバルシート設計室 | D9: 16119083 | E9: 802-2212-0081-000 | F9: 8164 | G9: 320D | I9: 1月 | J9: 44923 | K9: 鈴木
A10: 完了 | B10: 7 | C10: グローバルシート設計室 | D10: 16119084 | E10: 802-2212-0166-000 | F10: 8034 | G10: 612W | I10: 1月 | J10: 44923 | K10: 鈴木
A11: 完了 | B11: 8 | C11: グローバルシート設計室 | D11: 16119085 | E11: 802-2212-0163-000 | F11: 8037 | G11: D74A | I11: 1月 | J11: 44923 | K11: 鈴木
A12: 完了 | B12: 9 | C12: グローバルシート設計室 | D12: 16119086 | E12: 802-2212-0167-000 | F12: 8033 | G12: D25B | I12: 1月 | J12: 44923 | K12: 鈴木
A13: 完了 | B13: 10 | C13: グローバルシート設計室 | D13: 16119087 | E13: 802-2212-0131-000 | F13: 8078 | G13: YY8 | I13: 1月 | J13: 44923 | K13: 鈴木
A14: 完了 | B14: 11 | C14: グローバルシート設計室 | D14: 16119088 | E14: 802-2212-0019-000 | F14: 8298 | G14: D03B Fr開発 | I14: 1月 | J14: 44923 | K14: 鈴木
A15: 完了 | B15: 12 | C15: グローバルシート設計室 | D15: 16119089 | E15: 802-2212-0128-000 | F15: 8081 | G15: D90B | I15: 1月 | J15: 44923 | K15: 鈴木
A16: 完了 | B16: 13 | C16: グローバルシート設計室 | D16: 16119090 | E16: 802-2301-0109-000 | F16: 8368 | G16: D92A/D54B | I16: 2月 | J16: 44965 | K16: 鈴木
A17: 完了 | B17: 14 | C17: グローバルシート設計室 | D17: 16119091 | E17: 802-2301-0130-000 | F17: 8321 | G17: 3列 B-EV | I17: 2月 | J17: 44965 | K17: 鈴木
A18: 完了 | B18: 15 | C18: グローバルシート設計室 | D18: 16119092 | E18: 802-2301-0142-000 | F18: 8291 | G18: 320D | I18: 2月 | J18: 44965 | K18: 鈴木
A19: 完了 | B19: 16 | C19: グローバルシート設計室 | D19: 16119093 | E19: 802-2301-0103-000 | F19: 8382 | G19: 612W | I19: 2月 | J19: 44965 | K19: 鈴木
A20: 完了 | B20: 17 | C20: グローバルシート設計室 | D20: 16119094 | E20: 802-2301-0105-000 | F20: 8380 | G20: D74A | I20: 2月 | J20: 44965 | K20: 鈴木
... A25: 完了 | B25: 22 | C25: グローバルシート設計室 | D25: 16119099 | E25: 802-2301-0028-000 | F25: 8512 | G25: B-SUV Fr開発 MY | I25: 2月 | J25: 44960 | K25: 鈴木
A26: 完了 | B26: 23 | C26: グローバルシート設計室 | D26: 16119100 | F26: 8599 | G26: D92A/D54B | I26: 3月 | J26: 44994 | K26: 鈴木
A27: 完了 | B27: 24 | C27: グローバルシート設計室 | D27: 16119101 | F27: 8634 | G27: 3列 B-EV | I27: 3月 | J27: 44994 | K27: 鈴木
A28: 完了 | B28: 25 | C28: グローバルシート設計室 | D28: 16119102 | F28: 8635 | G28: 320D | I28: 3月 | J28: 44994 | K28: 鈴木
A29: 完了 | B29: 26 | C29: グローバルシート設計室 | D29: 16119103 | F29: 8648 | G29: D74A | I29: 3月 | J29: 44994 | K29: 鈴木
A30: 完了 | B30: 27 | C30: グローバルシート設計室 | D30: 16119104 | F30: 8664 | G30: D90B | I30: 3月 | J30: 44994 | K30: 鈴木
A31: 完了 | B31: 28 | C31: グローバルシート設計室 | D31: 16119105 | E31: 802-2302-0068-000 | F31: 8687 | G31: 612W | I31: 3月 | J31: 44984 | K31: 鈴木
A32: 完了 | B32: 29 | C32: グローバルシート設計室 | D32: 16119106 | E32: 802-2302-0059-000 | F32: 8706 | G32: D25B | I32: 3月 | J32: 44984 | K32: 鈴木
A33: 完了 | B33: 30 | C33: グローバルシート設計室 | D33: 16119107 | F33: 8719 | G33: YY8 | I33: 3月 | J33: 44994 | K33: 鈴木
A34: 完了 | B34: 31 | C34: グローバルシート設計室 | D34: 16119108 | F34: 857 | G34: B-SUV 2列 | I34: 3月 | J34: 44994 | K34: 鈴木
A35: 完了 | B35: 32 | C35: グローバルシート設計室 | D35: 16119109 | F35: 856 | G35: B-SUV Fr開発 MY | I35: 3月 | J35: 44994 | K35: 鈴木
A36: 完了 | B36: 33 | C36: グローバルシート設計室 | D36: 16119110 | F36: 8863 | G36: D92A/D54B | I36: 4月 | J36: 45016 | K36: 鈴木
A37: 完了 | B37: 34 | C37: グローバルシート設計室 | D37: 16119111 | F37: 8827 | G37: B-SUV 2列 | I37: 4月 | J37: 45016 | K37: 鈴木
A38: 完了 | B38: 35 | C38: グローバルシート設計室 | D38: 16119112 | F38: 8951 | G38: 320D | I38: 4月 | J38: 45016 | K38: 鈴木
A39: 完了 | B39: 36 | C39: グローバルシート設計室 | D39: 16119113 | F39: 8843 | G39: 612W | I39: 4月 | J39: 45016 | K39: 鈴木
A40: 完了 | B40: 37 | C40: グローバルシート設計室 | D40: 16119114 | F40: 8881 | G40: D90B | I40: 4月 | J40: 45016 | K40: 鈴木
A41: 完了 | B41: 38 | C41: グローバルシート設計室 | D41: 16119115 | F41: 8844 | G41: D42H | I41: 4月 | J41: 45016 | K41: 鈴木
A42: 完了 | B42: 39 | C42: グローバルシート設計室 | D42: 16119116 | F42: 8845 | G42: 524D(612W) | I42: 4月 | J42: 45016 | K42: 鈴木
A43: 完了 | B43: 40 | C43: グローバルシート設計室 | D43: 16119117 | F43: 8841 | G43: D38H | I43: 4月 | J43: 45016 | K43: 鈴木
A44: 完了 | B44: 41 | C44: グローバルシート設計室 | D44: 16119118 | F44: 9335 | G44: D92A/D54B | I44: 5月 | J44: 45044 | K44: 鈴木
...

Sheet BX→ｼｰﾄﾃﾞﾊﾞｲｽ
A1: 2024年 | C1: エンジニアリングサービス部 見積書・請求書発行管理台帳 | H1: 見積書(税抜金額)
A2: 企業名： | C2: トヨタ紡織(株)
A3: タスク | B3: No | C3: 部署名 | D3: 見積/請求番号 | E3: 発注番号 | F3: 業務計画書No | G3: 案件名 | H3: 見積金額 | I3: 見積月 | J3: 発行日 | K3: 発行者 | L3: 備考
A4: 完了 | B4: 1 | C4: シート機能品設計部第2設計室 | D4: 16117014 | E4: BX-22-012 | F4: - | G4: DASデータまとめ | I4: 1月 | J4: 44903 | K4: 鈴木
A5: 完了 | B5: 2 | C5: シート機能品設計部第2設計室 | D5: 16117015 | E5: BX-22-013 | F5: - | G5: DASデータまとめ | I5: 2月 | J5: 44937 | K5: 鈴木
A6: 完了 | B6: 3 | C6: シート機能品設計部第2設計室 | D6: 16117016 | F6: - | G6: DASデータまとめ | I6: 3月 | J6: 44966 | K6: 鈴木
A7: 完了 | B7: 4 | C7: シートデバイス設計部 | D7: 16117017 | F7: - | G7: DASデータまとめ | I7: 4月 | J7: 44999 | K7: 鈴木
A8: 完了 | B8: 5 | C8: シートデバイス設計部 | D8: 16117018 | F8: - | G8: DASデータまとめ | I8: 5月 | J8: 45023 | K8: 鈴木
A9: 完了 | B9: 6 | C9: シートデバイス設計部 | D9: 16117019 | F9: - | G9: DASデータまとめ | I9: 6月 | J9: 45063 | K9: 鈴木
A10: 完了 | B10: 7 | C10: シートデバイス設計部 | D10: 16117020 | F10: - | G10: DASデータまとめ | I10: 7月 | J10: 45085 | K10: 鈴木
A11: 完了 | B11: 8 | C11: シートデバイス設計部 | D11: 16117021 | F11: - | G11: DASデータまとめ | I11: 8月 | J11: 45112 | K11: 鈴木
A12: 完了 | B12: 9 | C12: シートデバイス設計部 | D12: 16117022 | F12: - | G12: DASデータまとめ | I12: 9月 | J12: 45148 | K12: 鈴木
A13: 完了 | B13: 10 | C13: シートデバイス設計部 | D13: 16117023 | F13: - | G13: DASデータまとめ | I13: 10月 | J13: 45183 | K13: 齊藤
A14: 進行中 | B14: 11 | C14: シートデバイス設計部 | D14: 16117024 | F14: - | G14: DASデータまとめ | I14: 11月 | J14: 45210 | K14: 齊藤
A15: 見積着手 | B15: 12 | C15: シートデバイス設計部 | D15: 16117025 | F15: - | G15: DASデータまとめ | I15: 12月 | J15: 45243 | K15: 齊藤
B16: 13 | C16: シートデバイス設計部 | D16: 16117026 | F16: - | G16: DASデータまとめ | I16: 1月 | J16: 45266 | K16: 齊藤
B17: 14 | C17: シートデバイス設計部 | D17: 16117027 | F17: - | G17: DASデータまとめ | I17: 2月 | J17: 44944 | K17: 齊藤
B18: 15 | C18: シートデバイス設計部 | D18: 16117028 | F18: - | G18: DASデータまとめ | I18: 3月 | J18: 44963 | K18: 齊藤
B19: 16 | C19: シートデバイス設計部 | D19: 16117029 | F19: - | G19: DASデータまとめ | I19: 4月 | J19: 44998 | K19: 齊藤
B20: 17 | C20: シートデバイス設計部 | D20: 16117030 | F20: - | G20: DASデータまとめ | I20: 5月 | J20: 45024 | K20: 齊藤
B21: 18 | C21: デバイス開発領域 | D21: 16117031 | F21: - | G21: DASデータまとめ | I21: 6月 | J21: 45056 | K21: 齊藤
B22: 19 | C22: デバイス開発領域 | D22: 16117032 | F22: - | G22: DASデータまとめ | I22: 7月 | J22: 45087 | K22: 齊藤
B23: 20 | C23: デバイス開発領域 | D23: 16117033 | F23: - | G23: DASデータまとめ | I23: ８月 | J23: 45115 | K23: 齊藤
B24: 21 | C24: デバイス開発領域 | D24: 16117034 | F24: - | G24: DASデータまとめ | I24: 9月 | J24: 45510 | K24: 齊藤
B25: 22 | C25: デバイス開発領域 | D25: 16117035 | F25: - | G25: DASデータまとめ | I25: 10月 | J25: 45544 | K25: 久目形
B26: 23 | C26: デバイス開発領域 | D26: 16117036 | F26: - | G26: DASデータまとめ | I26: 11月 | J26: 45583 | K26: 久目形
B27: 24 | C27: デバイス開発領域 | D27: 16117037 | F27: - | G27: DASデータまとめ | I27: 12月 | J27: 45604 | K27: 久目形
... B34: 31 | C34: デバイス開発領域 | D34: 16117044 | F34: - | G34: DASデータまとめ | I34: 7月 | J34: 45817 | K34: 久目形
B35: 32 | C35: デバイス開発領域 | D35: 16117045 | F35: - | G35: DASデータまとめ | I35: 8月 | J35: ’25/7/4 | K35: 久目形
B36: 33 | C36: デバイス開発領域 | D36: 16117046 | F36: - | G36: DASデータまとめ | I36: 9月 | J36: ’25/8/6 | K36: 久目形
B37: 34 | C37: デバイス開発領域 | D37: 16117047 | F37: - | G37: DASデータまとめ | I37: 10月 | J37: ’25/9/8 | K37: 久目形
B38: 35 | C38: デバイス開発領域 | D38: 16117048 | F38: - | G38: DASデータまとめ | I38: 11月 | J38: ’25/10/13 | K38: 久目形
B39: 36 | C39: デバイス開発領域 | D39: 16117049 | F39: - | G39: DASデータまとめ | I39: 12月 | J39: ’25/11/10 | K39: 久目形
B40: 37 | C40: デバイス開発領域 | D40: 16117050 | F40: - | G40: DASデータまとめ | I40: 1月 | J40: 45996 | K40: 久目形
B41: 38 | D41: 16117051
B42: 39 | D42: 16117052
B43: 40 | D43: 16117053
B44: 41 | D44: 16117054
B45: 42 | D45: 16117055
B46: 43 | D46: 16117056
...

Sheet ND
A1: 2024年 | C1: エンジニアリングサービス部 見積書・請求書発行管理台帳 | H1: 見積書(税抜金額)
A2: 企業名： | C2: トヨタ紡織(株)
A3: タスク | B3: No | C3: 部署名 | D3: 見積/請求番号 | E3: 発注番号 | F3: 業務計画書No | G3: 案件名 | H3: 見積金額 | I3: 見積月 | J3: 発行日 | K3: 発行者 | L3: 備考
A4: 完了 | B4: 1 | C4: ドアトリム設計部第1ドアトリム設計室 | D4: 16116026 | E4: 401-2212-0002-000 | F4: ITK08120 | G4: 700W他_号口管理 | I4: 1月 | J4: 44914 | K4: 鈴木
A5: 完了 | B5: 2 | C5: ドアトリム設計部第2ドアトリム設計室 | D5: 16116027 | E5: 404-2212-0012-000 | F5: ITK08207 | G5: D90B | I5: 1月 | J5: 44921 | K5: 鈴木
A6: 完了 | B6: 3 | C6: ドアトリム設計部第2ドアトリム設計室 | D6: 16116028 | E6: 404-2212-0011-000 | F6: ITK08206 | G6: 478D | I6: 1月 | J6: 44921 | K6: 鈴木
A7: 完了 | B7: 4 | C7: ドアトリム設計部第2ドアトリム設計室 | D7: 16116029 | E7: 404-2301-0009-000 | F7: 8451 | G7: D90B | I7: 2月 | J7: 44945 | K7: 鈴木
A8: 完了 | B8: 5 | C8: ドアトリム設計部第2ドアトリム設計室 | D8: 16116030 | E8: 404-2301-0008-000 | F8: 8487 | G8: 478D | I8: 2月 | J8: 44945 | K8: 鈴木
A9: 完了 | B9: 6 | C9: ドアトリム設計部第1ドアトリム設計室 | D9: 16116031 | E9: 401-2301-0001-000 | F9: 8524 | G9: 700W他_号口管理 | I9: 2月 | J9: 44950 | K9: 鈴木
A10: 完了 | B10: 7 | C10: ドアトリム設計部第1ドアトリム設計室 | D10: 16116032 | E10: 401-2302-0001-000 | F10: 8770 | G10: 700W他_号口管理 | I10: 3月 | J10: 44974 | K10: 鈴木
A11: 完了 | B11: 8 | C11: ドアトリム設計部第2ドアトリム設計室 | D11: 16116033 | E11: 404-2303-0002-000 | F11: 8814 | G11: D90B | I11: 3月 | J11: 44995 | K11: 鈴木
A12: 完了 | B12: 9 | C12: ドアトリム設計部第1ドアトリム設計室 | D12: 16116034 | F12: 9007 | G12: 700W他_号口管理 | I12: 4月 | J12: 45007 | K12: 鈴木
A13: 完了 | B13: 10 | C13: ドアトリム設計部先行設計室 | D13: 16116035 | F13: 9109 | G13: 競争力BMC | I13: 4月 | J13: 45016 | K13: 鈴木
A14: 完了 | B14: 11 | C14: ドアトリム設計部第1ドアトリム設計室 | D14: 16116036 | F14: 9178 | G14: 700W他_号口管理 | I14: 5月 | J14: 45027 | K14: 鈴木
A15: 完了 | B15: 12 | C15: ドアトリム設計部先行設計室 | D15: 16116037 | F15: 9176 | G15: 競争力BMC | I15: 5月 | J15: 45028 | K15: 鈴木
A16: 完了 | B16: 13 | C16: ドアトリム設計部第1ドアトリム設計室 | D16: 16116038 | F16: 9432 | G16: 700W他_号口管理 | I16: 6月 | J16: 45078 | K16: 鈴木
A17: 完了 | B17: 14 | C17: ドアトリム設計部先行設計室 | D17: 16116039 | F17: 9408 | G17: 競争力BMC | I17: 6月 | J17: 45078 | K17: 鈴木
A18: 完了 | B18: 15 | C18: ドアトリム設計部第1ドアトリム設計室 | D18: 16116040 | F18: 9841 | G18: 700W他_号口管理 | I18: 7月 | J18: 45099 | K18: 鈴木
A19: 完了 | B19: 16 | C19: ドアトリム設計部先行設計室 | D19: 16116041 | F19: 9842 | G19: 競争力BMC | I19: 7月 | J19: 45097 | K19: 鈴木
A20: 完了 | B20: 17 | C20: ドアトリム設計部先行設計室 | D20: 16116042 | F20: 10060 | G20: 競争力BMC | I20: 8月 | J20: 45121 | K20: 鈴木
A21: 完了 | B21: 18 | C21: ドアトリム設計部第1ドアトリム設計室 | D21: 16116043 | F21: 10069 | G21: 700W他_号口管理 | I21: 8月 | J21: 45119 | K21: 鈴木
A22: 完了 | B22: 19 | C22: ドアトリム設計部第1ドアトリム設計室 | D22: 16116044 | F22: 10283 | G22: 700W他_号口管理 | I22: 9月 | J22: 45138 | K22: 鈴木
A23: 完了 | B23: 20 | C23: ドアトリム設計部先行設計室 | D23: 16116045 | F23: 10310 | G23: 競争力BMC | I23: 9月 | J23: 45140 | K23: 鈴木
... A26: 進行中 | B26: 23 | C26: ドアトリム設計部第1ドアトリム設計室 | D26: 16116048 | F26: 10863 | G26: 700W他_号口管理 | I26: 11月 | J26: 45202 | K26: 齊藤
A27: 進行中 | B27: 24 | C27: ドアトリム設計部先行設計室 | D27: 16116049 | F27: ITK10868 | G27: 競争力BMC | I27: 11月 | J27: 45210 | K27: 齊藤
A28: 見積完了 | B28: 25 | C28: ドアトリム設計部第1ドアトリム設計室 | D28: 16116050 | F28: 11107 | G28: 700W他_号口管理 | I28: 12月 | J28: 45234 | K28: 齊藤
B29: 26 | C29: ドアトリム設計部先行設計室 | D29: 16116051 | F29: 11296 | G29: 競争力BMC | I29: 12月 | J29: 45250 | K29: 齊藤
B30: 27 | C30: ドアトリム設計部 | D30: 16116052 | F30: 11343 | G30: SHC部品開発 | I30: 11月 | J30: 45252 | K30: 齊藤
B31: 28 | C31: ドアトリム設計部 | D31: 16116053 | F31: 11367 | G31: SHC部品開発委託 | I31: 12月 | J31: 45267 | K31: 齊藤
B32: 29 | C32: ドアトリム設計部第1ドアトリム設計室 | D32: 16116054 | F32: 11433 | G32: 700W他_号口管理 | I32: 1月 | J32: 45267 | K32: 齊藤
B33: 30 | C33: ドアトリム設計部先行設計室 | D33: 16116055 | F33: 11607 | G33: 競争力BMC | I33: 1月 | J33: 45279 | K33: 齊藤
B34: 31 | C34: ドアトリム設計部先行設計室 | D34: 16116056 | F34: 11607 | G34: 競争力BMC | I34: 2月 | J34: 45303 | K34: 齊藤
B35: 32 | C35: ドアトリム設計部第1ドアトリム設計室 | D35: 16116057 | F35: 11882 | G35: 700W他_号口管理 | I35: 2月 | J35: 45306 | K35: 齊藤
B36: 33 | C36: ドアトリム設計部 | D36: 16116058 | F36: 11960 | G36: SHC部品開発委託 | I36: 2月 | J36: 45323 | K36: 齊藤
B37: 34 | C37: ドアトリム設計部第1ドアトリム設計室 | D37: 16116059 | F37: 120044 | G37: 700W他_号口管理 | I37: 3月 | J37: 45334 | K37: 齊藤
B38: 35 | C38: ドアトリム設計部先行設計室 | D38: 16116060 | F38: 12034 | G38: 競争力BMC | I38: 3月 | J38: 45334 | K38: 齊藤
B39: 36 | C39: ドアトリム設計部 | D39: 16116061 | F39: 12203 | G39: SHC部品開発委託 | I39: 3月 | J39: 45358 | K39: 齊藤
B40: 37 | C40: ドアトリム設計部先行設計室 | D40: 16116062 | F40: ITK12307 | G40: 競争力BMC | I40: 4月 | J40: 45377 | K40: 齊藤
B41: 38 | C41: ドアトリム設計部 | D41: 16116063 | F41: ITK12486 | G41: 700W他_号口管理 | I41: 4月 | J41: 45379 | K41: 齊藤
B42: 39 | C42: ドアトリム設計部 | D42: 16116064 | F42: ITK12598 | G42: 700W他_号口管理 | I42: 5月 | J42: 45397 | K42: 齊藤
...

Sheet ACT
A1: 2024年 | C1: エンジニアリングサービス部 見積書・請求書発行管理台帳 | H1: 見積書(税抜金額)
A2: 企業名： | C2: トヨタ紡織(株)
A3: タスク | B3: No | C3: 部署名 | D3: 見積/請求番号 | E3: 発注番号 | F3: 業務計画書No | G3: 案件名 | H3: 見積金額 | I3: 見積月 | J3: 発行日 | K3: 発行者 | L3: 備考
A4: 完了 | B4: 1 | C4: ACT事業室 | D4: 16118008 | E4: 802-2212-0096-000 | F4: 8141 | G4: 航空機シート | I4: 1月 | J4: 44923 | K4: 鈴木
A5: 完了 | B5: 2 | C5: ACT事業室 | D5: 16118009 | E5: 802-2301-0094-000 | F5: 8398 | G5: 航空機シート | I5: 2月 | J5: 44965 | K5: 鈴木
A6: 完了 | B6: 3 | C6: ACT事業室 | D6: 16118010 | F6: 8735 | G6: 航空機シート | I6: 3月 | J6: 44994 | K6: 鈴木
A7: 完了 | B7: 4 | C7: ACT事業室 | D7: 16118011 | F7: 9031 | G7: 航空機シート | I7: 4月 | J7: 45016 | K7: 鈴木
A8: 完了 | B8: 5 | C8: ACT事業室 | D8: 16118012 | F8: 9352 | G8: 航空機シート | I8: 5月 | J8: 45044 | K8: 鈴木
A9: 完了 | B9: 6 | C9: ACT事業室 | D9: 16118013 | F9: 9520 | G9: 航空機シート | I9: 6月 | J9: 45078 | K9: 鈴木
A10: 完了 | B10: 7 | C10: ACT事業室 | D10: 16118014 | F10: 9880 | G10: 航空機シート | I10: 7月 | J10: 45103 | K10: 鈴木
A11: 完了 | B11: 8 | C11: ACT事業室 | D11: 16118015 | F11: 10208 | G11: 航空機シート | I11: 8月 | J11: 45128 | K11: 鈴木
A12: 完了 | B12: 9 | C12: ACT事業室 | D12: 16118016 | F12: 10439 | G12: 航空機シート | I12: 9月 | J12: 45160 | K12: 鈴木
A13: 完了 | B13: 10 | C13: ACT事業室 | D13: 16118017 | F13: 10611 | G13: 航空機シート | I13: 10月 | J13: 45198 | K13: 齊藤
A14: 進行中 | B14: 11 | C14: ACT事業室 | D14: 16118018 | F14: 11000 | G14: 航空機シート | I14: 11月 | J14: 45225 | K14: 齊藤
B15: 12 | C15: ACT事業室 | D15: 16118019 | F15: 11322 | G15: 航空機シート | I15: 12月 | J15: 45221 | K15: 齊藤
B16: 13 | C16: ACT事業室 | D16: 16118020 | F16: ITK11574 | G16: 航空機シート | I16: 1月 | J16: 45275 | K16: 齊藤
B17: 14 | C17: ACT事業室 | D17: 16118021 | F17: 11818 | G17: 航空機シート | I17: 2月 | J17: 45310 | K17: 齊藤 | L17: 金額変更により取り消し（No,16）
B18: 15 | C18: ACT事業室 | D18: 16118022 | F18: 12146 | G18: 航空機シート | I18: 3月 | J18: 45337 | K18: 齊藤
B19: 16 | C19: ACT事業室 | D19: 16118023 | F19: 11818 | G19: 航空機シート | I19: 2月 | J19: 45341 | K19: 齊藤 | L19: No,14の再見積もり（工数変更による金額変更）
B20: 17 | C20: ACT事業室 | D20: 16118024 | F20: ITK12428 | G20: 航空機シート | I20: 4月 | J20: 45377 | K20: 齊藤
B21: 18 | C21: ACT事業部 | D21: 16118025 | F21: ITK12682 | G21: 航空機シート | I21: 5月 | J21: 45401 | K21: 齊藤
B22: 19 | C22: ACT事業部 | D22: 16118026 | F22: ITK12931 | G22: 航空機シート | I22: 6月 | J22: 45433 | K22: 齊藤
B23: 20 | C23: ACT事業部 | D23: 16118027 | F23: 13259 | G23: 航空機シート | I23: 7月 | J23: 45467 | K23: 齊藤
B24: 21 | C24: ACT事業部 | D24: 16118028 | F24: 13561 | G24: 航空機シート | I24: 8月 | J24: '24/7/16 | K24: 齊藤
B25: 22 | C25: ACT事業部 | D25: 16118029 | F25: 13835 | G25: 航空機シート | I25: 9月 | J25: '24/9/2 | K25: 齊藤
B26: 23 | C26: ACT事業部 | D26: 16118030 | F26: 14067 | G26: 航空機シート | I26: 10月 | J26: '24/10/3 | K26: 久目形
B27: 24 | C27: ACT事業部 | D27: 16118032 | F27: 14359 | G27: 航空機シート | I27: 11月 | J27: '24/11/1 | K27: 久目形
B28: 25 | C28: ACT事業部 | D28: 16118033 | F28: 14582 | G28: 航空機シート | I28: 12月 | J28: '24/11/26 | K28: 久目形
B29: 26 | C29: ACT事業部 | D29: 16118034 | F29: 14896 | G29: 航空機シート | I29: 1月 | J29: 45645 | K29: 久目形
B30: 27 | C30: ACT事業部 | D30: 16118035 | F30: 15156 | G30: 航空機シート | I30: 2月 | J30: 2025/1/29 | K30: 久目形
B31: 28 | C31: ACT事業部 | D31: 16118036 | F31: 15392 | G31: 航空機シート | I31: 3月 | J31: 2025/2/26 | K31: 久目形
B32: 29 | D32: 16118037
B33: 30 | D33: 16118038
B34: 31 | D34: 16118039
B35: 32 | D35: 16118040
B36: 33 | D36: 16118041
B37: 34 | D37: 16118042
B38: 35 | D38: 16118043
B39: 36 | D39: 16118044
B40: 37 | D40: 16118045
...

Sheet NT
A1: 2024年 | C1: エンジニアリングサービス部 見積書・請求書発行管理台帳 | H1: 見積書(税抜金額)
A2: 企業名： | C2: トヨタ紡織(株)
A3: タスク | B3: No | C3: 部署名 | D3: 見積/請求番号 | E3: 発注番号 | F3: 業務計画書No | G3: 案件名 | H3: 見積金額 | I3: 見積月 | J3: 発行日 | K3: 発行者 | L3: 備考
A4: 完了 | B4: 1 | C4: 内外装トリム設計部第３トリム設計室 | D4: 16112041 | E4: A93-2212-0009-000 | F4: ITK08246 | G4: 200D | I4: 1月 | J4: 44916 | K4: 鈴木
A5: 完了 | B5: 2 | C5: 内外装トリム設計部第３トリム設計室 | D5: 16112042 | E5: A93-2212-0013-000 | F5: ITK08244 | G5: 設計支援 | I5: 1月 | J5: 44916 | K5: 鈴木
A6: 完了 | B6: 3 | C6: 内外装トリム設計部第３トリム設計室 | D6: 16112043 | E6: A93-2301-0001-000 | F6: 8501 | G6: 263D | I6: 1月 | J6: 44944 | K6: 鈴木
A7: 完了 | B7: 4 | C7: 内外装トリム設計部第３トリム設計室 | D7: 16112044 | E7: A93-2301-0006-000 | F7: 8530 | G7: 200D | I7: 2月 | J7: 44950 | K7: 鈴木
A8: 完了 | B8: 5 | C8: 内外装トリム設計部第３トリム設計室 | D8: 16112045 | E8: A93-2301-0009-000 | F8: 8531 | G8: 設計支援 | I8: 2月 | J8: 44950 | K8: 鈴木
A9: 完了 | B9: 6 | C9: 内外装トリム設計部第３トリム設計室 | D9: 16112046 | E9: A93-2302-0012-000 | F9: 8774 | G9: 設計支援 | I9: 3月 | J9: 44977 | K9: 鈴木
A10: 完了 | B10: 7 | C10: 内外装トリム設計部第３トリム設計室 | D10: 16112047 | E10: A93-2302-0008-000 | F10: 8788 | G10: 200D | I10: 3月 | J10: 44992 | K10: 鈴木
A11: 完了 | B11: 8 | C11: 内外装トリム設計部第３トリム設計室 | D11: 16112048 | F11: 9066 | G11: 設計支援 | I11: 4月 | J11: 45016 | K11: 鈴木
A12: 完了 | B12: 9 | C12: 内外装トリム設計部第３トリム設計室 | D12: 16112049 | F12: 9358 | G12: 設計支援 | I12: 5月 | J12: 45040 | K12: 鈴木
A13: 完了 | B13: 10 | C13: 内外装トリム設計部第３トリム設計室 | D13: 16112050 | F13: 9607 | G13: 設計支援 | I13: 6月 | J13: 45071 | K13: 鈴木
A14: 完了 | B14: 11 | C14: 内外装トリム設計部第３トリム設計室 | D14: 16112051 | F14: 9904 | G14: 設計支援 | I14: 7月 | J14: 45099 | K14: 鈴木
A15: 完了 | B15: 12 | C15: 内外装トリム設計部第３トリム設計室 | D15: 16112052 | F15: 10182 | G15: 設計支援 | I15: 8月 | J15: 45126 | K15: 鈴木
A16: 完了 | B16: 13 | C16: 内外装トリム設計部第３トリム設計室 | D16: 16112053 | F16: 10462 | G16: 設計支援 | I16: 9月 | J16: 45167 | K16: 鈴木
A17: 完了 | B17: 14 | C17: 内外装トリム設計部第３トリム設計室 | D17: 16112054 | F17: 10769 | G17: 設計支援 | I17: 10月 | J17: 45196 | K17: 齊藤
A18: 完了 | B18: 15 | C18: 内外装トリム設計部第３トリム設計室 | D18: 16112055 | F18: 11061 | G18: 設計支援 | I18: 11月 | J18: 45225 | K18: 齊藤
A19: 完了 | B19: 16 | C19: 内外装トリム設計部第３トリム設計室 | D19: 16112056 | F19: 11328 | G19: 設計支援 | I19: 12月 | J19: 45254 | K19: 齊藤
B20: 17 | C20: 内外装トリム設計部第３トリム設計室 | D20: 16112057 | F20: 11605 | G20: 設計支援 | I20: 1月 | J20: 45279 | K20: 齊藤
B21: 18 | C21: 内外装トリム設計部第３トリム設計室 | D21: 16112058 | F21: 11904 | G21: 設計支援 | I21: 2月 | J21: 45310 | K21: 齊藤
B22: 19 | C22: 内外装トリム設計部第３トリム設計室 | D22: 16112059 | F22: 12154 | G22: 設計支援 | I22: 3月 | J22: 45345 | K22: 齊藤
B23: 20 | C23: 内外装トリム設計部第３トリム設計室 | D23: 16112060 | F23: ITK12414 | G23: 設計支援 | I23: 4月 | J23: 45377 | K23: 齊藤
B24: 21 | C24: 内外装トリム設計部第３トリム設計室 | D24: 16112061 | F24: ITK12747 | G24: 設計支援 | I24: 5月 | J24: 45407 | K24: 齊藤
B25: 22 | C25: 内外装トリム設計部第３トリム設計室 | D25: 16112062 | F25: ITK12999 | G25: 設計支援 | I25: 6月 | J25: 45435 | K25: 齊藤
B26: 23 | C26: 内外装トリム設計部第３トリム設計室 | D26: 16112063 | F26: TBN-24-003 | G26: 設計標準化業務 | I26: 6月 | J26: 24/5/28 | K26: 齊藤
B27: 24 | C27: 内外装トリム設計部第３トリム設計室 | D27: 16112064 | F27: ITK13033 | G27: 400D | I27: 6月 | J27: 24/5/31 | K27: 齊藤
B28: 25 | C28: 内外装トリム設計部第３トリム設計室 | D28: 16112065 | F28: TBN-24-004 | G28: 設計標準化業務 | I28: 7月 | J28: 24/6/17 | K28: 齊藤
B29: 26 | C29: 内外装トリム設計部第３トリム設計室 | D29: 16112066 | F29: 13295 | G29: 設計支援 | I29: 7月 | J29: 45464 | K29: 齊藤
B30: 27 | C30: 内外装トリム設計部第３トリム設計室 | D30: 16112067 | F30: 13311 | G30: 400D | I30: 7月 | J30: 45470 | K30: 齊藤
B31: 28 | C31: 内外装トリム設計部第３トリム設計室 | D31: 16112068 | F31: 13578 | G31: 設計支援 | I31: 8月 | J31: '24/7/18 | K31: 齊藤
B32: 29 | C32: 内外装トリム設計部第３トリム設計室 | D32: 16112069 | F32: 13580 | G32: 400D | I32: 8月 | J32: '24/7/18 | K32: 齊藤
B33: 30 | C33: 内外装トリム設計部第３トリム設計室 | D33: 16112070 | F33: TBN-24-008 | G33: 設計標準化業務 | I33: 8月 | J33: '24/7/22 | K33: 齊藤
B34: 31 | C34: 内外装トリム設計部第３トリム設計室 | D34: 16112071 | F34: 13797 | G34: 190D | I34: 8月 | J34: '24/8/8 | K34: 齊藤
B35: 32 | C35: 内外装トリム設計部第３トリム設計室 | D35: 16112072 | F35: 13828 | G35: 400D | I35: 9月 | J35: '24/8/23 | K35: 齊藤
B36: 33 | C36: 内外装トリム設計部第３トリム設計室 | D36: 16112073 | F36: 13829 | G36: 設計支援 | I36: 9月 | J36: '24/8/23 | K36: 齊藤
B37: 34 | C37: 内外装トリム設計部第３トリム設計室 | D37: 16112074 | F37: TBN-24-008 | G37: 設計標準化業務 | I37: 9月 | J37: '24/8/23 | K37: 齊藤
B38: 35 | C38: 内外装トリム設計部第３トリム設計室 | D38: 16112075 | F38: 13904 | G38: 190D | I38: 9月 | J38: '24/9/6 | K38: 久目形
B39: 36 | C39: 内外装トリム設計部第３トリム設計室 | D39: 16112076 | F39: TBN-24-013 | G39: 設計標準化業務 | I39: 10月 | J39: '24/9/20 | K39: 久目形
B40: 37 | C40: 内外装トリム設計部第３トリム設計室 | D40: 16112077 | F40: 14115 | G40: 400D | I40: 10月 | J40: '24/9/20 | K40: 久目形
...

Sheet 内外装先行開発部
A1: 2024年 | C1: エンジニアリングサービス部 見積書・請求書発行管理台帳 | H1: 見積書(税抜金額)
A2: 企業名： | C2: トヨタ紡織(株)
A3: タスク | B3: No | C3: 部署名 | D3: 見積/請求番号 | E3: 発注番号 | F3: 業務計画書No | G3: 案件名 | H3: 見積金額 | I3: 見積月 | J3: 発行日 | K3: 発行者 | L3: 備考
A4: 完了 | B4: 1 | C4: 内外装先行開発部照明開発室 | D4: 16115009 | F4: 9163 | G4: 280Dイルミ | I4: 4月 | J4: 45021 | K4: 鈴木
A5: 完了 | B5: 2 | C5: 内外装先行開発部照明開発室 | D5: 16115010 | F5: 9554 | G5: 280Dイルミ | I5: 5月 | J5: 45062 | K5: 鈴木
A6: 完了 | B6: 3 | C6: 内外装先行開発部照明開発室 | D6: 16115011 | F6: 9629 | G6: 280Dイルミ | I6: 6月 | J6: 45078 | K6: 鈴木
A7: 完了 | B7: 4 | C7: 内外装先行開発部照明開発室 | D7: 16115012 | F7: 9959 | G7: 280Dイルミ | I7: 7月 | J7: 45119 | K7: 鈴木
A8: 完了 | B8: 5 | C8: 内外装先行開発部照明開発室 | D8: 16115013 | F8: 10231 | G8: 280Dイルミ | I8: 8月 | J8: 45148 | K8: 鈴木
A9: 完了 | B9: 6 | C9: 内外装先行開発部照明開発室 | D9: 16115014 | F9: 10482 | G9: 280Dイルミ | I9: 9月 | J9: 45167 | K9: 鈴木
A10: 完了 | B10: 7 | C10: 内外装先行開発部照明開発室 | D10: 16115015 | F10: 10853 | G10: 280Dイルミ | I10: 10月 | J10: 45198 | K10: 齊藤
A11: 完了 | B11: 8 | C11: 内外装先行開発部照明開発室 | D11: 16115016 | F11: 11092 | G11: 280Dイルミ | I11: 11月 | J11: 45236 | K11: 齊藤
A12: 完了 | B12: 9 | C12: 内外装先行開発部照明開発室 | D12: 16115017 | F12: ITK11380 | G12: 280Dイルミ | I12: 12月 | J12: 45275 | K12: 齊藤
B13: 10 | C13: 内外装先行開発部照明開発室 | D13: 16115018 | F13: ITK11372 | G13: 650Dイルミ | I13: 12月 | J13: 45278 | K13: 齊藤
B14: 11 | C14: 内外装先行開発部照明開発室 | D14: 16115019 | F14: 11693 | G14: 280Dイルミ | I14: 1月 | J14: 45287 | K14: 齊藤
B15: 12 | C15: 内外装先行開発部照明開発室 | D15: 16115020 | F15: 11698 | G15: 650Dイルミ | I15: 1月 | J15: 45287 | K15: 齊藤
B16: 13 | C16: 内外装先行開発部照明開発室 | D16: 16115021 | F16: 11930 | G16: 650Dイルミ | I16: 2月 | J16: 45323 | K16: 齊藤
B17: 14 | C17: 内外装先行開発部照明開発室 | D17: 16115022 | F17: 12190 | G17: 650Dイルミ | I17: 3月 | J17: 45349 | K17: 齊藤
B18: 15 | C18: 内外装先行開発部照明開発室 | D18: 16115023 | F18: ITK12758 | G18: 650Dイルミ | I18: 5月 | J18: 45407 | K18: 齊藤
B19: 16 | C19: ドアトリム設計部照明設計室 | D19: 16115024 | F19: ITK12846 | G19: 650Dイルミ | I19: 6月 | J19: 45432 | K19: 齊藤
B20: 17 | C20: ドアトリム設計部照明設計室 | D20: 16115025 | F20: 13272 | G20: 650Dイルミ | I20: 7-8月 | J20: 45470 | K20: 齊藤
B21: 18 | C21: ドアトリム設計部照明設計室 | D21: 16115026 | F21: 13767 | G21: 650Dイルミ | I21: 9月 | J21: '24/8/21 | K21: 齊藤
B22: 19 | C22: ドアトリム設計部照明設計室 | D22: 16115027 | F22: 14031 | G22: 650Dイルミ | I22: 10月 | J22: '24/9/20 | K22: 久目形
B23: 20 | C23: ドアトリム設計部照明設計室 | D23: 16115028 | F23: 14309 | G23: 650Dイルミ | I23: 11月 | J23: '24/10/23 | K23: 久目形
B24: 21 | C24: ドアトリム設計部照明設計室 | D24: 16115029 | F24: 14480 | G24: 650Dイルミ | I24: 12月 | J24: '24/11/26 | K24: 久目形
B25: 22 | C25: ドアトリム設計部照明設計室 | D25: 16115030 | F25: 14760 | G25: 650Dイルミ | I25: 1月 | J25: 45645 | K25: 久目形
B26: 23 | C26: ドアトリム設計部照明設計室 | D26: 16115031 | F26: 15103 | G26: 650Dイルミ | I26: 2月 | J26: 202/2/29 | K26: 久目形
B27: 24 | C27: ドアトリム設計部照明設計室 | D27: 16115032 | F27: 15224 | G27: 650Dイルミ | I27: 3月 | J27: 2025/2/19 | K27: 久目形
B28: 25 | C28: ドアトリム設計部照明設計室 | D28: 16115033 | F28: ITK15502 | G28: 650Dイルミ | I28: 4月 | J28: 45743 | K28: 丸山
B29: 26 | D29: 16115034
B30: 27 | D30: 16115035
B31: 28 | D31: 16115036
B32: 29 | D32: 16115037
B33: 30 | D33: 16115038
B34: 31 | D34: 16115039
B35: 32 | D35: 16115040
B36: 33 | D36: 16115041
B37: 34 | D37: 16115042
B38: 35 | D38: 16115043
B39: 36 | D39: 16115044
B40: 37 | D40: 16115045
...

Sheet 内外装実験部
A1: 2024年 | C1: エンジニアリングサービス部 見積書・請求書発行管理台帳 | H1: 見積書(税抜金額)
A2: 企業名： | C2: トヨタ紡織(株)
A3: タスク | B3: No | C3: 部署名 | D3: 見積/請求番号 | E3: 発注番号 | F3: 業務計画書No | G3: 案件名 | H3: 見積金額 | I3: 見積月 | J3: 発行日 | K3: 発行者 | L3: 備考
B4: 1 | C4: 内外装事業本部 内外装実験部 | D4: 16111001 | G4: CAE用物性データ変換 | I4: 1月 | J4: 45308 | K4: 齊藤
B5: 2 | C5: 内外装事業本部 内外装実験部 | D5: 16111002 | G5: CAE用物性データ変換 | I5: 3月 | J5: 45342 | K5: 齊藤
B6: 3 | D6: 16111003
B7: 4 | D7: 16111004
B8: 5 | D8: 16111005
B9: 6 | D9: 16111006
B10: 7 | D10: 16111007
B11: 8 | D11: 16111008
B12: 9 | D12: 16111009
B13: 10 | D13: 16111010
B14: 11 | D14: 16111011
B15: 12 | D15: 16111012
B16: 13 | D16: 16111013
B17: 14 | D17: 16111014
... B50: 47 | D50: 16111047

Sheet SH→設計品質改善室
A1: 2024年 | C1: エンジニアリングサービス部 見積書・請求書発行管理台帳 | H1: 見積書(税抜金額)
A2: 企業名： | C2: トヨタ紡織(株)
A3: タスク | B3: No | C3: 部署名 | D3: 見積/請求番号 | E3: 発注番号 | F3: 業務計画書No | G3: 案件名 | H3: 見積金額 | I3: 見積月 | J3: 発行日 | K3: 発行者 | L3: 備考
A4: 完了 | B4: 1 | C4: シートホーム推進部 | D4: 16120016 | E4: SQ2021-0062 | F4: - | G4: 品質監査業務支援 | I4: 1月 | J4: 44903 | K4: 鈴木
A5: 完了 | B5: 2 | C5: シートホーム推進部 | D5: 16120017 | E5: SQ2021-0061 | F5: - | G5: 設計品質改善会 | I5: 1月 | J5: 44903 | K5: 鈴木
A6: 完了 | B6: 3 | C6: シートホーム推進部 | D6: 16120018 | E6: SQ2021-0067 | F6: - | G6: 品質監査業務支援 | I6: 2月 | J6: 44937 | K6: 鈴木
A7: 完了 | B7: 4 | C7: シートホーム推進部 | D7: 16120019 | E7: SQ2021-0066 | F7: - | G7: 設計品質改善会 | I7: 2月 | J7: 44937 | K7: 鈴木
A8: 完了 | B8: 5 | C8: シートホーム推進部 | D8: 16120020 | F8: - | G8: 品質監査業務支援 | I8: 3月 | J8: 44966 | K8: 鈴木
A9: 完了 | B9: 6 | C9: シートホーム推進部 | D9: 16120021 | F9: - | G9: 設計品質改善会 | I9: 3月 | J9: 44966 | K9: 鈴木
A10: 完了 | B10: 7 | C10: シートホーム推進部 | D10: 16120022 | F10: - | G10: 品質監査業務支援 | I10: 4月 | J10: 44999 | K10: 鈴木
A11: 完了 | B11: 8 | C11: シートホーム推進部 | D11: 16120023 | F11: - | G11: 設計品質改善会 | I11: 4月 | J11: 44999 | K11: 鈴木
A12: 完了 | B12: 9 | C12: シートホーム推進部 | D12: 16120024 | F12: - | G12: 品質監査業務支援 | I12: 5月 | J12: 45023 | K12: 鈴木
A13: 完了 | B13: 10 | C13: シートホーム推進部 | D13: 16120025 | F13: - | G13: 設計品質改善会 | I13: 5月 | J13: 45023 | K13: 鈴木
A14: 完了 | B14: 11 | C14: シートホーム推進部 | D14: 16120026 | F14: - | G14: 品質監査業務支援 | I14: 6月 | J14: 45063 | K14: 鈴木
A15: 完了 | B15: 12 | C15: シートホーム推進部 | D15: 16120027 | F15: - | G15: 設計品質改善会 | I15: 6月 | J15: 45063 | K15: 鈴木
A16: 完了 | B16: 13 | C16: シートホーム推進部 | D16: 16120028 | F16: - | G16: 品質監査業務支援 | I16: 7月 | J16: 45085 | K16: 鈴木
A17: 完了 | B17: 14 | C17: シートホーム推進部 | D17: 16120029 | F17: - | G17: 設計品質改善会 | I17: 7月 | J17: 45085 | K17: 鈴木
A18: 完了 | B18: 15 | C18: シートホーム推進部 | D18: 16120030 | F18: - | G18: 品質監査業務支援 | I18: 8月 | J18: 45112 | K18: 鈴木
A19: 完了 | B19: 16 | C19: シートホーム推進部 | D19: 16120031 | F19: - | G19: 設計品質改善会 | I19: 8月 | J19: 45112 | K19: 鈴木
... A27: 見積着手 | B27: 24 | C27: シートホーム推進部 | D27: 16120039 | F27: - | G27: 設計品質改善会 | I27: 12月 | J27: 45243 | K27: 齊藤
B28: 25 | C28: シートホーム推進部 | D28: 16120040 | F28: - | G28: 品質監査業務支援 | I28: 1月 | J28: 45276 | K28: 齊藤
B29: 26 | C29: シートホーム推進部 | D29: 16120041 | F29: - | G29: 設計品質改善会の運営のサポート | I29: 1月 | J29: 45276 | K29: 齊藤
B30: 27 | C30: シートホーム推進部 | D30: 16120042 | F30: - | G30: 品質監査業務支援 | I30: 2月 | J30: 45309 | K30: 齊藤
B31: 28 | C31: シートホーム推進部 | D31: 16120043 | F31: - | G31: 設計品質改善会 | I31: 2月 | J31: 45309 | K31: 齊藤
B32: 29 | C32: シートホーム推進部 | D32: 16120044 | F32: - | G32: 品質監査業務支援 | I32: 3月 | J32: 45328 | K32: 齊藤
B33: 30 | C33: シートホーム推進部 | D33: 16120045 | F33: - | G33: 設計品質改善会 | I33: 3月 | J33: 45328 | K33: 齊藤
B34: 31 | C34: シートホーム推進部 | D34: 16120046 | F34: - | G34: 品質監査業務支援 | I34: 4月 | J34: 45364 | K34: 齊藤
B35: 32 | C35: シートホーム推進部 | D35: 16120047 | F35: - | G35: 設計品質改善会 | I35: 4月 | J35: 45364 | K35: 齊藤
B36: 33 | C36: 設計品質改善室 | D36: 16120048 | F36: - | G36: 品質監査業務支援 | I36: 5月 | J36: 45390 | K36: 齊藤
B37: 34 | C37: 設計品質改善室 | D37: 16120049 | F37: - | G37: 設計品質改善会 | I37: 5月 | J37: 45390 | K37: 齊藤
B38: 35 | C38: 設計品質改善室 | D38: 16120050 | F38: - | G38: 品質監査業務支援 | I38: 6月 | J38: 45422 | K38: 齊藤
B39: 36 | C39: 設計品質改善室 | D39: 16120051 | F39: - | G39: 設計品質改善会 | I39: 6月 | J39: 45422 | K39: 齊藤
... B55: 52 | C55: 設計品質改善室 | D55: 16120067 | F55: - | G55: 設計品質改善会 | I55: 2月 | J55: 45672 | K55: 久目形
B56: 53 | C56: 設計品質改善室 | D56: 16120068 | F56: - | G56: 品質監査業務支援（内外装） | I56: 2月 | J56: 202/2/29 | K56: 久目形
B57: 54 | C57: 設計品質改善室 | D57: 16120069 | F57: - | G57: 品質監査業務支援 | I57: 3月 | J57: 45699 | K57: 久目形
B58: 55 | C58: 設計品質改善室 | D58: 16120070 | F58: - | G58: 設計品質改善会 | I58: 3月 | J58: 45699 | K58: 久目形
B59: 56 | C59: 設計品質改善室 | D59: 16120071 | F59: - | G59: 品質監査業務支援 | I59: 4月 | J59: 45735 | K59: 久目形
B60: 57 | C60: 設計品質改善室 | D60: 16120072 | F60: - | G60: 設計品質改善会 | I60: 4月 | J60: 45735 | K60: 久目形
B61: 58 | C61: 設計品質改善室 | D61: 16120073 | F61: - | G61: 品質監査業務支援（内外装） | I61: 4月 | J61: 45735 | K61: 久目形
B62: 59 | C62: 設計品質改善室 | D62: 16120074 | F62: - | G62: 品質監査業務支援 | I62: 5月 | J62: 45761 | K62: 丸山
...

Sheet 技管
A1: 2024年 | C1: エンジニアリングサービス部 見積書・請求書発行管理台帳 | H1: 見積書(税抜金額)
A2: 企業名： | C2: トヨタ紡織(株)
A3: タスク | B3: No | C3: 部署名 | D3: 見積/請求番号 | E3: 発注番号 | F3: 業務計画書No | G3: 案件名 | H3: 見積金額 | I3: 見積月 | J3: 発行日 | K3: 発行者 | L3: 備考
A4: 完了 | B4: 1 | C4: 技術管理部 | D4: 16124001 | E4: SQ2021-0062 | F4: - | G4: 単価改定 | I4: 1月 | J4: 45651 | K4: 久目形
B5: 2 | D5: 16124002
B6: 3 | D6: 16124003
B7: 4 | D7: 16124004
B8: 5 | D8: 16124005
B9: 6 | D9: 16124006
B10: 7 | D10: 16124007
B11: 8 | D11: 16124008
B12: 9 | D12: 16124009
B13: 10 | D13: 16124010
B14: 11 | D14: 16124011
B15: 12 | D15: 16124012
